Workbook

Sheet Ene´26
A1: Estado de Resultados 2026
A2: Concepto | B2: 46023 | C2: %
A3: Ventas Netas | B3: =ExportFacturacion[[#Totals],[Subtotal]] -> 132113966 | C3: 1
A4: Descuentos Realizados | B4: =ExportFacturacion[[#Totals],[Descuento]] -> 25674604 | C4: =(B4*C3)/B3 -> 0.19433679
A5: Total Ingresos | B5: =B3-B4 -> 1.0643936e+08 | C5: 1
A6: Costo total | B6: =ExportFacturacion[[#Totals],[Costo]] -> 16767018 | C6: 0.33
A7: Utilidad Marginal | B7: =B5-B6 -> 89672344 | C7: =(B7*C5)/B5 -> 0.84247352
A10: GASTOS VARIABLES | B10: =SUM(B11:B18) -> 1.359734e+08 | C10: =(B10*$C$5)/$B$5 -> 1.2774729
A11: COMISIONES BANCARIAS | B11: =+Gastos!C9 -> 447789.58 | C11: =(B11*$C$5)/$B$5 -> 0.0042069923
A12: COMISIONES DISTRIBUIDORES | B12: =+Gastos!C14 -> 0 | C12: =(B12*$C$5)/$B$5 -> 0
A13: COMISIONES VENTAS | B13: =+Gastos!C12 -> 4516360 | C13: =(B13*$C$5)/$B$5 -> 0.042431295
A14: EXTRAORDINARIOS | B14: =+Gastos!C30 -> 85455941 | C14: =(B14*$C$5)/$B$5 -> 0.80286032
A15: FLETES | B15: =+Gastos!C37 -> 1271343.6 | C15: =(B15*$C$5)/$B$5 -> 0.011944299
A16: IMPUESTOS | B16: =+Gastos!C171 -> 44281968 | C16: =(B16*$C$5)/$B$5 -> 0.41603
A17: MARKETING | B17: 0 | C17: =(B17*$C$5)/$B$5 -> 0
A18: PUESTA EN MARCHA | B18: 0 | C18: =(B18*$C$5)/$B$5 -> 0
A20: GASTOS FIJOS | B20: =SUM(B21:B22) -> 11341495 | C20: =(B20*$C$5)/$B$5 -> 0.10655358
A21: LOCAL | B21: =+Gastos!C184 -> 3134666.8 | C21: =(B21*$C$5)/$B$5 -> 0.02945026
A22: SUELDOS | B22: =+Gastos!C190 -> 8206828 | C22: =(B22*$C$5)/$B$5 -> 0.077103318
A24: GASTOS TOTALES | B24: =+B10+B20 -> 1.473149e+08
A26: UTILIDAD NETA | B26: =B7-B10-B20 -> -57642552 | C26: =(B26*C5)/B5 -> -0.54155297
A29: INVERSIONES
A30: INVERSIONES

Sheet Gastos
A1: Fecha | B1: Descripción | C1: Importe | D1: Categoría | E1: SubCategoría
A2: 46024 | B2: Comision Servicio de Cuenta | C2: 40806.45 | D2: Impuestos | E2: Comisiones Bancarias
A3: 46027 | B3: Debito Com. Varias | Transf. al Ext. | C3: 15141 | D3: Impuestos | E3: Comisiones Bancarias
A4: 46027 | B4: Debito Com. Varias | Transf. al Ext. | C4: 189262.5 | D4: Impuestos | E4: Comisiones Bancarias
A5: 46037 | B5: Debito Com. Varias | Transf. al Ext. | C5: 14857.75 | D5: Impuestos | E5: Comisiones Bancarias
A6: 46037 | B6: Debito Com. Varias | Transf. al Ext. | C6: 185721.88 | D6: Impuestos | E6: Comisiones Bancarias
A7: 46044 | B7: Comision Gestion Transferancia Fondos entre Bancos | C7: 1000 | D7: Comisiones Bancarias | E7: Comisiones Bancarias
A8: 46045 | B8: Comision Gestion Transferancia Fondos entre Bancos | C8: 1000 | D8: Comisiones Bancarias | E8: Comisiones Bancarias
B9: Comisiones Bancarias | C9: =SUM(C2:C8) -> 447789.58
B10: Pago | Comisiones de Ventas Dic´2025 | Stefania | C10: 3146145 | D10: Comisiones Ventas | E10: Comisiones Ventas
B11: Pago | Comisiones de Ventas Dic´2025 | Rosselin | C11: 1370215 | D11: Comisiones Ventas | E11: Comisiones Ventas
B12: Comisiones de Ventas | C12: =SUM(C10:C11) -> 4516360
B13: Comisiones Javier Nov´25 | D13: Comisiones Ventas | E13: Comisiones Ventas
B14: Comisiones Distribuidores | C14: =SUM(C13) -> 0
A15: 46027 | B15: Pago | Muñoz Ciro Tiziano | Fact 0008 | C15: 300000 | D15: Otros Servicios | E15: Puesta en Marcha | F15: Instalacion de 2 motores frigorificos
A16: 46027 | B16: Pago | Desarrollo de Soluciones Digitales | Fact 0046 | | C16: 609909.4 | D16: Otros Servicios | E16: App Sumar | F16: Servicio APP Enero 2026
A17: 46027 | B17: Pago | Guangdong Mingtai Baking Equipment Co LTD | Fact AR250827-04 | C17: 23680524 | D17: Activos | E17: Importacion | F17: Hornos
A18: 46029 | B18: Pago | Nicolas Torres Manuel | Fact 131 | C18: 72600 | D18: Otros Servicios | E18: Gastos Administrativos | F18: Bidones de agua
A19: 46029 | B19: Pago | Martino Karina Veronica | Fact 11003 | C19: 214353.4 | D19: Otros Servicios | E19: Gastos Administrativos | F19: Remitos x 3
A20: 46035 | B20: Pago | Antonio Francisco Celio | Fact 37046 | C20: 2395028.4 | D20: Activos | E20: Importacion | F20: Manometros aneroides
A21: 46037 | B21: Pago | Guangdong Mingtai Baking Equipment Co LTD | Fact AR250904-05 | C21: 45464715 | D21: Activos | E21: Importacion | F21: Hornos
A22: 46038 | B22: Pago | Maria del Pilar Otero | Fact 279 | C22: 59500 | D22: Otros Servicios | E22: Gastos Administrativos | F22: Certificacion de Firmas (Con libro)
A23: 46038 | B23: Pago | Nicolas Torres Manuel | Fact 149 | C23: 72600 | D23: Otros Servicios | E23: Gastos Administrativos | F23: Bidones de agua
A24: 46038 | B24: Pago | Bureau Veritas Argentina | Fact 00003-00264675 | C24: 2709743.4 | D24: Otros Servicios | E24: Gastos Administrativos | F24: Reinscripcion en registro de Importador de equipos gastronomicos
A25: 46042 | B25: Pago | Muñoz Ciro Tiziano | Fact 0011 | C25: 540000 | D25: Otros Servicios | E25: Puesta en Marcha | F25: Instalacion de 2 motores frigorificos
A26: 46044 | B26: Transf | Transferencia entre Cuentas | Credicoop | C26: 1000 | D26: Otros Servicios | E26: Gastos Administrativos | F26: Transf a cuenta nueva Fornitalia Credicop
... A29: 46050 | B29: Pago | Lagatta Carlos Adrian | Fact 4841 | C29: 506383.35 | D29: Activos | E29: Refacciones | F29: Motocompresores y conexiones de cobre
B30: Extraordinarios | C30: =SUM(C15:C29) -> 85455941
A31: 46027 | B31: Pago | Autoelevadores y Gruas | Fact 7637 | C31: 667243.4 | D31: Logistica | E31: Fletes y Transportes | F31: Flete 10 cajones Bocayya a Fornitalia
A32: 46028 | B32: Pago | Pou Rosa Laura | Flete | Fact 226 | C32: 144143.4 | D32: Logistica | E32: Fletes y Transportes | F32: Flete traslado de productos
A33: 46030 | B33: Pago | Pou Rosa Laura | Flete | Fact 227 | C33: 190533.4 | D33: Logistica | E33: Fletes y Transportes | F33: Flete traslado de productos
A34: 46042 | B34: Pago | Pou Rosa Laura | Flete | Fact 228 | C34: 72600 | D34: Logistica | E34: Fletes y Transportes | F34: Flete traslado de productos
A35: 46048 | B35: Pago | Pou Rosa Laura | Flete | Fact 232 | C35: 60500 | D35: Logistica | E35: Fletes y Transportes | F35: Flete traslado de productos
A36: 46048 | B36: Pago | Pou Rosa Laura | Flete | Fact 233 | C36: 136323.4 | D36: Logistica | E36: Fletes y Transportes | F36: Flete traslado de productos
B37: Fletes | C37: =SUM(C31:C36) -> 1271343.6
A38: 46024 | B38: Imp. Ing. Brutos Sircreb | C38: 1000 | D38: Impuestos | E38: Sircreb
A39: 46024 | B39: Impuesto Deb. Ley 25.413 | C39: 627.52 | D39: Impuestos | E39: Ley 25.413
A40: 46024 | B40: Impuesto Cre. Ley 25.413 | C40: 6000 | D40: Impuestos | E40: Ley 25.413
A41: 46024 | B41: Impuesto Deb. Ley 25.413 | C41: 6 | D41: Impuestos | E41: Ley 25.413
A42: 46024 | B42: IVA | C42: 8569.35 | D42: Impuestos | E42: Iva
...

Sheet Ventas Ene 2026 
A1: Tipo de Operacion | B1: ID Operacion | C1: Status | D1: Cliente | E1: Vendedor | F1: Descripcion | G1: Costo | H1: Subtotal | I1: Descuento | J1: Precio con Descuento
A2: Venta | B2: 356 | C2: Pendiente Despacho | D2: Ignacio Parise | E2: Roselin | F2: Horno Pro Gas 24-3 | H2: 10820000 | I2: =ExportFacturacion[[#This Row],[Subtotal]]*10% -> 1082000 | J2: =ExportFacturacion[[#This Row],[Subtotal]]-ExportFacturacion[[#This Row],[Descuento]] -> 9738000
A3: Venta | B3: 466 | C3: Pendiente Puesta Marcha | D3: Ezequiel Ignacio Demaestri | E3: Roselin | F3: Horno Pro Gas 6-1 | G3: 598486.37 | H3: 3867600 | I3: =ExportFacturacion[[#This Row],[Subtotal]]*20.69% -> 800206.44 | J3: =ExportFacturacion[[#This Row],[Subtotal]]-ExportFacturacion[[#This Row],[Descuento]] -> 3067393.6
A4: Venta | B4: 547 | C4: Cerrado | D4: Rodolfo Victor Ravina | E4: Roselin | F4: Horno Pro Gas 12-2 | G4: 1114422.9 | H4: 7000000 | I4: =ExportFacturacion[[#This Row],[Subtotal]]*18.57% -> 1299900 | J4: =ExportFacturacion[[#This Row],[Subtotal]]-ExportFacturacion[[#This Row],[Descuento]] -> 5700100
A5: Venta | B5: 605 | C5: Pendiente Puesta Marcha | D5: Sebastián Moya Ruíz | E5: Roselin | F5: Horno Pro Gas 12-2 | G5: 1114422.9 | H5: 7000000 | I5: =ExportFacturacion[[#This Row],[Subtotal]]*18.57% -> 1299900 | J5: =ExportFacturacion[[#This Row],[Subtotal]]-ExportFacturacion[[#This Row],[Descuento]] -> 5700100
A6: Venta | B6: 625 | C6: Cerrado | D6: Sebastián Moya Ruíz | E6: Roselin | F6: Aceitera | G6: 16557.34 | H6: 75100 | I6: 0 | J6: =ExportFacturacion[[#This Row],[Subtotal]]-ExportFacturacion[[#This Row],[Descuento]] -> 75100
F7: Aceitera | G7: 16557.34 | H7: 75100 | I7: 0 | J7: =ExportFacturacion[[#This Row],[Subtotal]]-ExportFacturacion[[#This Row],[Descuento]] -> 75100
F8: Aceitera | G8: 16557.34 | H8: 75100 | I8: 0 | J8: =ExportFacturacion[[#This Row],[Subtotal]]-ExportFacturacion[[#This Row],[Descuento]] -> 75100
A9: Venta | B9: 642 | C9: Pendiente Despacho | D9: Matias Alejandro Zuccotti | E9: Roselin | F9: Amasadora 5.2 kg | G9: 599897.5 | H9: 1844330 | I9: 0 | J9: =ExportFacturacion[[#This Row],[Subtotal]]-ExportFacturacion[[#This Row],[Descuento]] -> 1844330
A10: Venta | B10: 663 | C10: Pendiente Despacho | D10: Daniel Larraya | E10: Stefania | F10: Horno Pro Gas 6-1 | G10: 598486.37 | H10: 3867600 | I10: =ExportFacturacion[[#This Row],[Subtotal]]*20.69% -> 800206.44 | J10: =ExportFacturacion[[#This Row],[Subtotal]]-ExportFacturacion[[#This Row],[Descuento]] -> 3067393.6
A11: Venta | B11: 676 | C11: Cerrado | D11: Mariano Duran | E11: Lelia | F11: Horno FN2 Pro | G11: 398990.91 | H11: 2211000 | I11: =ExportFacturacion[[#This Row],[Subtotal]]*10% -> 221100 | J11: =ExportFacturacion[[#This Row],[Subtotal]]-ExportFacturacion[[#This Row],[Descuento]] -> 1989900
A12: Venta | B12: 677 | C12: Pendiente Despacho | D12: Jorge Alejandro Boscana | E12: Roselin | F12: Pala Redonde de Giro | G12: 28147.47 | H12: 80000 | I12: 0 | J12: =ExportFacturacion[[#This Row],[Subtotal]]-ExportFacturacion[[#This Row],[Descuento]] -> 80000
F13: Cepillo para piedra | G13: 29803.21 | H13: 120100 | I13: 0 | J13: =ExportFacturacion[[#This Row],[Subtotal]]-ExportFacturacion[[#This Row],[Descuento]] -> 120100
A14: Venta | B14: 680 | C14: Cerrado | D14: Marcelo Castillo | E14: Stefania | F14: Horno Pro Gas 12-2 | G14: 1114422.9 | H14: 7000000 | I14: =ExportFacturacion[[#This Row],[Subtotal]]*10% -> 700000 | J14: =ExportFacturacion[[#This Row],[Subtotal]]-ExportFacturacion[[#This Row],[Descuento]] -> 6300000
A15: Venta | B15: 685 | C15: Pendiente Puesta Marcha | D15: Lisandro Carrere | E15: Stefania | F15: Horno Pro Gas 16-2 | H15: 9180000 | I15: =ExportFacturacion[[#This Row],[Subtotal]]*12% -> 1101600 | J15: =ExportFacturacion[[#This Row],[Subtotal]]-ExportFacturacion[[#This Row],[Descuento]] -> 8078400
A16: Venta | B16: 691 | C16: Pendiente Despacho | D16: Norberto Ariel De Paoli | E16: Roselin | F16: Horno Pro Gas 90 | G16: 1120931.7 | H16: 4350000 | I16: =ExportFacturacion[[#This Row],[Subtotal]]*20% -> 870000 | J16: =ExportFacturacion[[#This Row],[Subtotal]]-ExportFacturacion[[#This Row],[Descuento]] -> 3480000
A17: Venta | B17: 692 | C17: Pendiente Despacho | D17: Lautaro Agustin Leyes | E17: Roselin | F17: Horno Pro Gas 90 | G17: 1120931.7 | H17: 4350000 | I17: =ExportFacturacion[[#This Row],[Subtotal]]*20% -> 870000 | J17: =ExportFacturacion[[#This Row],[Subtotal]]-ExportFacturacion[[#This Row],[Descuento]] -> 3480000
A18: Venta | B18: 699 | C18: Pendiente Despacho | D18: Javier Oscar Gauna | E18: Stefania | F18: Horno Pro Gas 16-2 | H18: 9180000 | I18: =ExportFacturacion[[#This Row],[Subtotal]]*19.61% -> 1800198 | J18: =ExportFacturacion[[#This Row],[Subtotal]]-ExportFacturacion[[#This Row],[Descuento]] -> 7379802
A19: Venta | B19: 704 | C19: Pendiente Puesta Marcha | D19: Thiago Nahuel Guevara | E19: Stefania | F19: Mesa fria dos puertas | G19: 1630897.6 | H19: 3949803 | I19: =ExportFacturacion[[#This Row],[Subtotal]]*25% -> 987450.75 | J19: =ExportFacturacion[[#This Row],[Subtotal]]-ExportFacturacion[[#This Row],[Descuento]] -> 2962352.2
A20: Venta | B20: 708 | C20: Pendiente Puesta Marcha | D20: Fabian Octavio Ancan Lomaquis | E20: Stefania | F20: Horno FN2 Pro | G20: 398990.91 | H20: 2211000 | I20: =ExportFacturacion[[#This Row],[Subtotal]]*5% -> 110550 | J20: =ExportFacturacion[[#This Row],[Subtotal]]-ExportFacturacion[[#This Row],[Descuento]] -> 2100450
A21: Venta | B21: 709 | C21: Pendiente Puesta Marcha | D21: Eduardo Matias Rodriguez | E21: Roselin | F21: Horno FN2 Pro | G21: 398990.91 | H21: 2211000 | I21: 0 | J21: =ExportFacturacion[[#This Row],[Subtotal]]-ExportFacturacion[[#This Row],[Descuento]] -> 2211000
A22: Venta | B22: 711 | C22: Pendiente Despacho | D22: Ivan Hidalgo | E22: Stefania | F22: Mesa fria dos puertas | G22: 1630897.6 | H22: 3949803 | I22: =ExportFacturacion[[#This Row],[Subtotal]]*33.32% -> 1316074.4 | J22: =ExportFacturacion[[#This Row],[Subtotal]]-ExportFacturacion[[#This Row],[Descuento]] -> 2633728.6
A23: Venta | B23: 714 | C23: Pendiente Puesta Marcha | D23: David Basualdo | E23: Roselin | F23: Horno Pro Gas 16-2 | H23: 9180000 | I23: =ExportFacturacion[[#This Row],[Subtotal]]*63% -> 5783400 | J23: =ExportFacturacion[[#This Row],[Subtotal]]-ExportFacturacion[[#This Row],[Descuento]] -> 3396600
A24: Venta | B24: 717 | C24: Pendiente Puesta Marcha | D24: Gustavo Sanguinetto | E24: Roselin | F24: Horno FN2 Pro | G24: 398990.91 | H24: 2211000 | I24: 0 | J24: =ExportFacturacion[[#This Row],[Subtotal]]-ExportFacturacion[[#This Row],[Descuento]] -> 2211000
A25: Venta | B25: 720 | C25: Pendiente Despacho | D25: Hernan Gustavo Novoa | E25: Stefania | F25: Horno Pro Gas 90 | G25: 1120931.7 | H25: 4350000 | I25: =ExportFacturacion[[#This Row],[Subtotal]]*20% -> 870000 | J25: =ExportFacturacion[[#This Row],[Subtotal]]-ExportFacturacion[[#This Row],[Descuento]] -> 3480000
A26: Venta | B26: 724 | C26: Pendiente Despacho | D26: Fabian Ariel Bonasegla | E26: Roselin | F26: Horno Pro Gas 16-2 | H26: 9180000 | I26: =ExportFacturacion[[#This Row],[Subtotal]]*20% -> 1836000 | J26: =ExportFacturacion[[#This Row],[Subtotal]]-ExportFacturacion[[#This Row],[Descuento]] -> 7344000
A27: Venta | B27: 725 | C27: Pendiente Despacho | D27: Javier Oscar Gauna | E27: Stefania | F27: Pala Redonde de Giro | G27: 28147.47 | H27: 80000 | I27: 0 | J27: =ExportFacturacion[[#This Row],[Subtotal]]-ExportFacturacion[[#This Row],[Descuento]] -> 80000
F28: Cepillo para piedra | G28: 29803.21 | H28: 120100 | I28: =ExportFacturacion[[#This Row],[Subtotal]]*5% -> 6005 | J28: =ExportFacturacion[[#This Row],[Subtotal]]-ExportFacturacion[[#This Row],[Descuento]] -> 114095
A29: Venta | B29: 727 | C29: Pendiente Despacho | D29: Claudia Fernanda Ulrich | E29: Stefania | F29: Horno Pro Gas 24-3 | H29: 10820000 | I29: =ExportFacturacion[[#This Row],[Subtotal]]*16.4% -> 1774480 | J29: =ExportFacturacion[[#This Row],[Subtotal]]-ExportFacturacion[[#This Row],[Descuento]] -> 9045520
F30: Amasadora 5.2 kg | G30: 599897.5 | H30: 1844330 | I30: =ExportFacturacion[[#This Row],[Subtotal]]*10% -> 184433 | J30: =ExportFacturacion[[#This Row],[Subtotal]]-ExportFacturacion[[#This Row],[Descuento]] -> 1659897
A31: Venta | B31: 729 | C31: Pendiente Despacho | D31: Diego Sise | E31: Roselin | F31: Horno Pro Gas 90 | G31: 1120931.7 | H31: 4350000 | I31: =ExportFacturacion[[#This Row],[Subtotal]]*20% -> 870000 | J31: =ExportFacturacion[[#This Row],[Subtotal]]-ExportFacturacion[[#This Row],[Descuento]] -> 3480000
A32: Venta | B32: 730 | C32: Pendiente Despacho | D32: Matias Iacono | E32: Roselin | F32: Horno FN2 Pro | G32: 398990.91 | H32: 2211000 | I32: =ExportFacturacion[[#This Row],[Subtotal]]*10% -> 221100 | J32: =ExportFacturacion[[#This Row],[Subtotal]]-ExportFacturacion[[#This Row],[Descuento]] -> 1989900
A33: Venta | B33: 732 | C33: Pendiente Despacho | D33: Oscar Alberto Jauregui | E33: Roselin | F33: Horno Pro Gas 90 | G33: 1120931.7 | H33: 4350000 | I33: =4350000*20% -> 870000 | J33: =ExportFacturacion[[#This Row],[Subtotal]]-ExportFacturacion[[#This Row],[Descuento]] -> 3480000
G34: =SUM(G2:G33) -> 16767018 | H34: =SUM(H2:H33) -> 132113966 | I34: =SUM(I2:I33) -> 25674604 | J34: =SUM(J2:J33) -> 1.0643936e+08

Sheet LISTA CONCEPTOS
A1: CUENTA | B1: SUBCUENTA
A2: Gasto de nómina | B2: ADQUISICION DE MERCANCIAS
A3: Gastos por servicios | B3: ALMACEN IFULL
A4: Gastos de venta | B4: ANTICIPO A PROVEEDORES
A5: Gastos financieros | B5: ASOCIACION NACIONAL DE TIENDAS DE AUTOSERVICIO Y DEPARTAMENTALES
A6: Gasto logistica | B6: CARGO NO IDENTIFICADO
A7: Reembolsos | B7: CASETAS
A8: Gastos de almacenaje | B8: COMISIONES BANCARIAS
A9: Viaticos Expo Pan WTC | B9: COMISIONES EUROFORNO
A10: Otros gastos operativos | B10: COMISIONES SOBRE VENTAS
A11: ANTICIPO A PROVEEDORES | B11: COMISIONES VENDEDORES
A12: CARGOS NO RECONOCIDOS BBVA | B12: CONSULTORIA ANA GPT
... A16: Gastos de Viaje y Transportacion | B16: EQUIPO DE PROTECCION PERSONAL
B17: EQUIPO PARA VENDEDORES (CARGADOR, USB,PILAS)
B18: ESTACIONAMIENTOS
B19: EXPO FOOD SERVICE DE MEXICO
B20: FERRETERIA Y HERRAMIENTAS PARA BODEGA TOLUCA
B21: GASOLINA FABIO
B22: GASTOS VARIOS
B23: GASTOS VARIOS (FABIO)
B24: HERRERIA BODEGA TOLUCA
B25: IMPUESTOS ANUALES
B26: IMPUESTOS FEDERALES
B27: IMPUESTOS ISR RET
B28: IMPUESTOS IVA RET
... B97: PUBLICIDAD DIGITAL MANTTO PAG. INTERNET-QUITO, ECUADOR
