Workbook

Sheet Dic'24
A1: Estado de Resultados 2024
A2: Concepto | B2: 45627 | C2: %
A3: Ventas Netas | B3: =+'Ventas Dic''24'!H19 -> 34207000 | C3: 1
A4: Descuentos Realizados | B4: =+'Ventas Dic''24'!H21 -> 3915650 | C4: =(B4*C3)/B3 -> 0.11446926
A5: Total Ingresos | B5: =B3-B4 -> 30291350 | C5: 1
A6: Costo total | B6: =+'Ventas Dic''24'!V19 -> 11188068 | C6: 0.33
A7: Utilidad Marginal | B7: =B5-B6 -> 19103282 | C7: =(B7*C5)/B5 -> 0.63065139
A10: GASTOS VARIABLES | B10: =SUM(B11:B16) -> 5295165.1 | C10: =(B10*C5)/B5 -> 0.17480783
A11: COMISIONES BANCARIAS | B11: =+'Gastos Galicia'!C6 -> 184592.49 | C11: =(B11*$C$5)/$B$5 -> 0.0060939011
A12: COMISIONES DISTRIBUIDORES | B12: ='Gastos Efectivo'!C6 -> 1915000 | C12: =(B12*$C$5)/$B$5 -> 0.063219368
A13: COMISIONES VENTAS | B13: =+'Gastos Efectivo'!C4 -> 1350000 | C13: =(B13*$C$5)/$B$5 -> 0.044567178
A14: EXTRAORDINARIOS | B14: =+'Gastos Galicia'!C11 -> 729474.42 | C14: =(B14*$C$5)/$B$5 -> 0.024081938
A15: FLETES | B15: =+'Gastos Galicia'!C14 -> 329843.04 | C15: =(B15*$C$5)/$B$5 -> 0.010889017
A16: IMPUESTOS | B16: =+'Gastos Galicia'!C113 -> 786255.12 | C16: =(B16*$C$5)/$B$5 -> 0.025956424
A18: GASTOS FIJOS | B18: =SUM(B19:B20) -> 5501239.3 | C18: =(B18*C15)/B15 -> 0.1816109
A19: LOCAL | B19: =+'Gastos Galicia'!C120+'Gastos Efectivo'!C14 -> 2057073.3 | C19: =(B19*$C$5)/$B$5 -> 0.067909596
A20: SUELDOS | B20: =+'Gastos Galicia'!C128+'Gastos Efectivo'!C20 -> 3444166 | C20: =(B20*$C$5)/$B$5 -> 0.1137013
A22: GASTOS TOTALES | B22: =+B10+B18 -> 10796404 | C22: =(B22*$C$5)/$B$5 -> 0.35641873
A24: UTILIDAD NETA | B24: =B7-B10-B18 -> 8306877.6 | C24: =(B24*C5)/B5 -> 0.27423267
A27: INVERSIONES (Certificaciones) | B27: =+'Gastos Galicia'!C135 -> 5327784

Sheet Gastos Galicia
A1: Fecha | B1: Descripción | C1: Retiros Débito | D1: Rubro | E1: Cuenta Contable
A2: 45631 | B2: Comisión Transferencia Internet | C2: 5715 | D2: Comisiones Bancarias | E2: Bancarias
A3: 45643 | B3: Descuento Comercio | PayWay | C3: 58963.25 | D3: Comisiones Bancarias | E3: PayWay
A4: 45652 | B4: Descuento Comercio | PayWay | C4: 69614.24 | D4: Comisiones Bancarias | E4: PayWay
A5: 46021 | B5: Comisión Mantenimiento de Cuenta | C5: 50300 | D5: Comisiones Bancarias | E5: Bancarias
B6: SUB TOTAL COMISIONES BANCARIAS | C6: =SUM(C2:C5) -> 184592.49
A7: 45631 | B7: Pago | Fundación Facultad Reg Santa Fe | Fc 4890 | Ensayo | C7: 358970 | D7: Extraordinarios | E7: Ensayo
A8: 45643 | B8: Pago | Mol y Band |Fc 3085 | Saldo Final | Mesas | C8: 181500 | D8: Extraordinarios | E8: Bases Hornos
A9: 45652 | B9: Pago | Antonio Francisco | Fc 34338 | Manómetro | C9: 63404 | D9: Extraordinarios | E9: Manómetro
A10: 45652 | B10: Pago | Francisco Ricardo José | Fc 1029 | Regulador | C10: 125600.42 | D10: Extraordinarios | E10: Regulador
B11: SUB TOTAL EXTRAORDINARIOS | C11: =SUM(C7:C10) -> 729474.42
A12: 45643 | B12: Pago | La Sevillanita | Fc 0327-02020633 | Envío Horno Catamarca Fernando | C12: 209843.04 | D12: Fletes | E12: Flete
A13: 46021 | B13: Pago | Racca Daniel | Fc 421 | Flete Tigre DAMIANO MARIANO | 2 Pro Gas | C13: 120000 | D13: Fletes | E13: Flete
B14: SUB TOTAL FLETES | C14: =SUM(C12:C13) -> 329843.04
A15: 45628 | B15: Impuesto Ley 25.413 | C15: 5.64 | D15: Impuestos | E15: Ley 25.413
A16: 45628 | B16: Impuesto Ley 25.413 | C16: 9.05 | D16: Impuestos | E16: Ley 25.413
A17: 45628 | B17: Impuesto Ley 25.413 | C17: 9.05 | D17: Impuestos | E17: Ley 25.413
A18: 45628 | B18: Impuesto Ley 25.413 | C18: 39.5 | D18: Impuestos | E18: Ley 25.413
A19: 45628 | B19: Impuesto Ley 25.413 | C19: 63.38 | D19: Impuestos | E19: Ley 25.413
A20: 45628 | B20: Impuesto Ley 25.413 | C20: 188.11 | D20: Impuestos | E20: Ley 25.413
A21: 45628 | B21: Impuesto Ley 25.413 | C21: 301.8 | D21: Impuestos | E21: Ley 25.413
A22: 45628 | B22: Impuesto Ley 25.413 | C22: 1888.92 | D22: Impuestos | E22: Ley 25.413
A23: 45628 | B23: Impuesto Ley 25.413 | C23: 15470.09 | D23: Impuestos | E23: Ley 25.413
A24: 45629 | B24: Impuesto Ley 25.413 | C24: 454.38 | D24: Impuestos | E24: Ley 25.413
A25: 45629 | B25: Impuesto Ley 25.413 | C25: 2926.42 | D25: Impuestos | E25: Ley 25.413
A26: 45629 | B26: Impuesto Ley 25.413 | C26: 2926.42 | D26: Impuestos | E26: Ley 25.413
... A112: 46021 | B112: Ingresos Brutos | C112: 1509 | D112: Impuestos | E112: IIBB
B113: SUB TOTAL IMPUESTOS | C113: =SUM(C15:C112) -> 786255.12
A114: 45628 | B114: Pago | Débito Automático | Prosegur Alarmas | Fc 0012-01783689 | C114: 75730.17 | D114: Local | E114: Alarma Local
A115: 45630 | B115: Pago | Débito Automático | Telecom Teléfonos | Fc 4264-04618390 | C115: 24431.64 | D115: Local | E115: Teléfonos
A116: 45631 | B116: Pago | Fuertes Viviana Patricia | Fc 0002-00000220 | Alquiler Dic'24 | C116: 251090 | D116: Local | E116: Alquiler
A117: 45636 | B117: Pago | Débito Automático | Soluciones Online - Xubio | Fc 00002-00390478 | C117: 124630 | D117: Local | E117: Sistema Contable
A118: 45638 | B118: Pago | Débito Automático | Telecom Internet Personal | Fc A6364-08736249 | C118: 90691.53 | D118: Local | E118: Internet
A119: 45646 | B119: Pago | Verónica Rigante | Fc 0866 | Honorarios Contables | C119: 220000 | D119: Local | E119: Honorarios Contables
B120: SUB TOTAL LOCAL | C120: =SUM(C114:C119) -> 786573.34
A121: 45628 | B121: Pago | Sueldo | Cynthia Fernández | Nov´24 | C121: 487737 | D121: Sueldos | E121: Sueldos
A122: 45628 | B122: Pago | Sueldo | Lelia Bertoni | Nov´24 | C122: 487737 | D122: Sueldos | E122: Sueldos
A123: 45632 | B123: Pago | Cargas Sociales | F931 | Nov´24 | C123: 508317.37 | D123: Sueldos | E123: Cargas Sociales
A124: 45636 | B124: Pago | Cargas Sindicales | FAECYS | 11/2024 | C124: 5901.48 | D124: Sueldos | E124: Faecys
A125: 45636 | B125: Pago | Débito Automático | Cargas Sindicales | INACAP | 11/2024 | C125: 8770.1 | D125: Sueldos | E125: Inacap
...

Sheet Gastos Efectivo
B2: Comisiones Cynthia |Sep|Oct|Nov´24 | C2: 705000 | D2: COMISIONES VENTAS | E2: COMISIONES
B3: Comisiones Lelia| Nov´24 | México | C3: 645000 | D3: COMISIONES VENTAS | E3: COMISIONES
B4: SUB TOTAL COMISIONES VENTAS | C4: =SUM(C2:C3) -> 1350000
B5: Pago Comisiones Javier | Nov y pendientes meses pasados | C5: 1915000 | D5: COMISIONES DISTRIBUIDORES | E5: COMISIONES
B6: SUB TOTAL COMISIONES VENTAS | C6: =SUM(C5:C5) -> 1915000
B7: Alquiler Local Dic'24 | C7: 921000 | D7: LOCAL | E7: ALQUILER
B8: Reposición Caja Chica | C8: 50000 | D8: LOCAL | E8: CAJA CHICA
A9: 45635 | B9: Gratificacion descarga hornos | C9: 20000 | D9: LOCAL | E9: IMPORTACIÓN
A10: 45635 | B10: Reposición Caja Chica | C10: 30000 | D10: LOCAL | E10: CAJA CHICA
A11: 45646 | B11: Reposición Caja Chica | C11: 49500 | D11: LOCAL | E11: CAJA CHICA
A12: 45653 | B12: Reposición Caja Chica | C12: 50000 | D12: LOCAL | E12: CAJA CHICA
A13: 45656 | B13: Pago Peones Orden Local | C13: 150000 | D13: LOCAL | E13: OTROS
B14: SUB TOTAL LOCAL | C14: =SUM(C7:C13) -> 1270500
A15: 45646 | B15: Aguinaldo Cynthia | C15: 100000 | D15: SUELDOS | E15: AGUINALDO
A16: 45646 | B16: Aguinaldo Lelia | C16: 43000 | D16: SUELDOS | E16: AGUINALDO
A17: 45653 | B17: Sueldo Cynthia | Dic´24 | C17: 250000 | D17: SUELDOS | E17: SUELDOS
A18: 45653 | B18: Sueldo Lelia| Dic´24 | C18: 200000 | D18: SUELDOS | E18: SUELDOS
A19: 45656 | B19: Sueldo Carolina | Dic´24 | C19: 1000000 | D19: SUELDOS | E19: SUELDOS
B20: SUB TOTAL SUELDOS | C20: =SUM(C15:C19) -> 1593000
B22: TOTAL | C22: =+C4+C14+C20+C6 -> 6128500

Sheet Ventas Dic'24
A1: OPERADOR | B1: FECHA | C1: PRODUCTO | D1: Nº Serie | E1: N° Despacho | F1: CLIENTE | G1: # | H1: VALOR Sin Descuento | I1: VALOR SIN IVA | J1: MONTO NETO | K1: IVA | L1: Tipo de IVA | M1: MONTO TOTAL | N1: Valor TOTAL Cotización CON IVA | O1: HSBC | P1: Efectivo / Morva | Q1: Total Pagado | R1: Por Cobrar | S1: FACTURADO | T1: CUIT | U1: Forma de Pago | V1: Costo Contable | W1: Comisión 3% | X1: Comisión 5% | Y1: Comisión 7%
A2: Lelia | B2: 45597 | C2: FN1 PRO | D2: 202410306 | E2: 24 001 | C04 196596 G | F2: PABLO FUENTES | G2: 1 | H2: 1080000 | I2: 1080000 | J2: 1080000 | K2: 226800 | L2: 0.21 | M2: 1306800 | N2: 1306800 | O2: 1416910 | P2: - | Q2: 1416910 | R2: 0 | S2: Factura B 0006 (Anticipo) Factura B 0007 (Saldo) | T2: 27310946945 | U2: HSBC | V2: 296472 | W2: 32400 | X2: 54000 | Y2: 75600
A3: Lelia | B3: 45628 | C3: PALA | D3: N/A | E3: N/A | F3: PABLO FUENTES | G3: 1 | H3: 91000 | I3: 91000 | J3: 91000 | K3: 19110 | L3: 0.21 | M3: 110110 | N3: 110110 | U3: HSBC | V3: 34368 | W3: 2730 | X3: 4550 | Y3: 6370
A4: Lelia | B4: 45638 | C4: PRO GAS 90 | D4: 24146001 | E4: 24 001 | C04 196596 G | F4: GERARDO TURRI | G4: 1 | H4: 4350000 | I4: 3915000 | J4: 3915000 | K4: 411075 | L4: 0.105 | M4: 4326075 | N4: 4326075 | O4: 4326075 | P4: - | Q4: 4326075 | R4: 0 | S4: Factura A 0044 | T4: 20115516761 | U4: HSBC | V4: 1201860 | W4: 117450 | X4: 195750 | Y4: 274050
A5: Lelia | B5: 45652 | C5: PRO GAS 106 | D5: G24038032011 | E5: 24 001 IC04 0985888 X | F5: WALJUL SRL | G5: 1 | H5: 3210000 | I5: 2889000 | J5: 1444500 | K5: 151672.5 | L5: 0.105 | M5: 1596172.5 | N5: 3040672.5 | O5: 1596173 | P5: 1444500 | Q5: 3040672.5 | R5: 0 | S5: Factura A 0048 | T5: 30717906833 | U5: HSBC | Efectivo | V5: 1267392 | W5: 86670 | X5: 144450 | Y5: 202230
A6: Lelia | B6: 45653 | C6: FN2 PRO | D6: 202410336 | E6: 24 001 | C04 196596 G | F6: CARLOS ALBERTO BULOG | G6: 1 | H6: 2010000 | I6: 2010000 | J6: 2010000 | K6: 422100 | L6: 0.21 | M6: 2432100 | N6: 2432100 | O6: 2432100 | P6: - | Q6: 2432100 | R6: 0 | S6: Factura A 0050 | T6: 20397058795 | U6: 6 Cuotas | HSBC | V6: 552108 | W6: 60300 | X6: 100500 | Y6: 140700
A7: Lelia | B7: 45653 | C7: PRO GAS 106 | D7: G24038032006 | E7: 24 001 IC04 0985888 X | F7: PRÓCERES SRL | G7: 1 | H7: 3210000 | I7: 2889000 | J7: 2889000 | K7: 303345 | L7: 0.105 | M7: 3192345 | N7: 3192345 | O7: 3192345 | P7: - | Q7: 3192345 | R7: 0 | S7: Factura A 0051 | T7: 30714010898 | U7: HSBC | V7: 1267392 | W7: 86670 | X7: 144450 | Y7: 202230 | Z7: 643700
A8: Cynthia | B8: 45596 | C8: FN1 PRO | D8: 202410301 | E8: 24 001 | C04 196596 G | F8: GUSTAVO BUEZAS | G8: 1 | H8: 1080000 | I8: 1080000 | J8: 1080000 | K8: 226800 | L8: 0.21 | M8: 1306800 | N8: 1306800 | O8: 1306800 | P8: 0 | Q8: 1306800 | R8: 0 | S8: Factura B 0005 (Anticipo) Factura B 0008 (Saldo) | T8: 20345204734 | U8: HSBC | 3 Cuotas | V8: 296472 | W8: 32400 | X8: 54000 | Y8: 75600
A9: Cynthia | B9: 45568 | C9: FN1 PRO | D9: 202410304 | E9: 24 001 | C04 196596 G | F9: EMIR MUSA | G9: 1 | H9: 1080000 | I9: 972000 | J9: 291600 | K9: 61236 | L9: 0.21 | M9: 352836 | N9: 1033236 | O9: 352836 | P9: 680400 | Q9: 1033236 | R9: 0 | S9: Factura B 0003 | T9: 20106597767 | U9: HSBC | Efectivo | V9: 296472 | W9: 29160 | X9: 48600 | Y9: 68040
A10: Cynthia | B10: 45632 | C10: PRO GAS 106 | D10: G24038032004 | E10: 24 001 IC04 0985888 X | F10: FABRIC CITY BELL SA | G10: 1 | H10: 3210000 | I10: 2728500 | J10: 818550 | K10: 85947.75 | L10: 0.105 | M10: 904497.75 | N10: 2814447.8 | O10: 904498 | P10: 1909950 | Q10: 2814448 | R10: -0.25 | S10: Factura A 0045 | T10: 30717748707 | U10: HSBC | Efectivo | V10: 1267392 | W10: 81855 | X10: 136425 | Y10: 190995
A11: Cynthia | B11: 45574 | C11: FN1 PRO | D11: 202410323 | E11: 24 001 | C04 196596 G | F11: PABLO BRAVO | G11: 1 | H11: 1080000 | I11: 1080000 | J11: 1080000 | K11: 226800 | L11: 0.21 | M11: 1306800 | N11: 1306800 | O11: 425073 | P11: 881650 | Q11: 1306723 | R11: 77 | S11: Factura B 0003 (Anticipo) Factura B 0009 (Saldo) | T11: 20435521275 | U11: Tarjeta | Efectivo | V11: 296472 | W11: 32400 | X11: 54000 | Y11: 75600
A12: Cynthia | B12: 45653 | C12: PRO GAS 106 | D12: G24038032001 | E12: 24 001 IC04 0985888 X | F12: DAMIANO MARIANO | G12: 2 | H12: 3210000 | I12: 5328600 | J12: 2664300 | K12: 279751.5 | L12: 0.105 | M12: 2944051.5 | N12: 5608351.5 | O12: 2944052 | P12: 2660000 | Q12: 5604052 | R12: 4299.5 | S12: Factura A 0049 | T12: 20321870253 | U12: HSBC | Efectivo | V12: 2534784 | W12: 159858 | X12: 266430 | Y12: 373002
A13: Cynthia | B13: 45653 | C13: PRO GAS 106 | D13: G24038032002 | E13: 24 001 IC04 0985888 X | F13: DAMIANO MARIANO | H13: 3210000
A14: Cynthia | B14: 45653 | C14: PALAS | D14: N/A | E14: N/A | F14: DAMIANO MARIANO | G14: 2 | H14: 91000 | I14: 0 | J14: 0 | K14: 0 | L14: 0 | M14: 0 | N14: BONIFICADO | Q14: 0 | V14: 34368 | W14: - | X14: - | Y14: - | Z14: 559455
A15: Javier | B15: 45621 | C15: PRO ELECTRICO 90 | D15: ES240380320006 | E15: 24 001 IC04 0985888 X | F15: RODRIGO GARCÍA | G15: 1 | H15: 3125000 | I15: 2968750 | J15: 1484375 | K15: 311718.75 | L15: 0.21 | M15: 1796093.8 | N15: 3280468.8 | O15: 1796094 | P15: 1484375 | Q15: 3280469 | R15: -0.25 | S15: Factura A 0043 | T15: 23412378539 | U15: HSBC | Efectivo | V15: 859236
A16: Javier | B16: 45635 | C16: FN2 PRO | D16: 202403602 | E16: 24 001 | C04 196596 G | F16: RODRIGO ALLEGRE | G16: 1 | H16: 2010000 | I16: 1809500 | J16: 904750 | K16: 189997.5 | L16: 0.21 | M16: 1094747.5 | N16: 1999497.5 | O16: 1094748 | P16: 905000 | Q16: 1999748 | R16: -250.5 | S16: Factura A 0046 | T16: 20380109485 | U16: HSBC | Efectivo | V16: 552108
A17: Javier | B17: 45635 | C17: MESA | D17: PO24/TA030 | E17: 24 001 IC04 0985888 X | F17: RODRIGO ALLEGRE | G17: 1 | H17: 1080000 | I17: 370000 | J17: 185000 | K17: 38850 | L17: 0.21 | M17: 223850 | N17: 408850 | O17: 223850 | P17: 185000 | Q17: 408850 | R17: 0 | U17: HSBC | Efectivo | V17: 129372
A18: Javier | B18: 45644 | C18: PRO HOUSE | D18: PT1816 9 of 10 | E18: 24 001 IC04 0985888 X | F18: DANIEL SALIVA | G18: 1 | H18: 1080000 | I18: 1080000 | J18: 1080000 | K18: 113400 | L18: 0.105 | M18: 1193400 | N18: 1193400 | O18: 1193400 | P18: - | Q18: 1193400 | R18: 0 | S18: Factura A 0047 | T18: 20269112213 | U18: HSBC | 3 Cuotas | V18: 301800
H19: 34207000 | I19: 30291350 | J19: 21018075 | K19: 3068604 | M19: 24086679 | N19: 33359954 | R19: 4125.5 | V19: 11188068
G21: Descuentos | H21: =+H19-I19 -> 3915650

Sheet LISTA CONCEPTOS
A1: CUENTA | B1: SUBCUENTA
A2: Gasto de nómina | B2: ADQUISICION DE MERCANCIAS
A3: Gastos por servicios | B3: ALMACEN IFULL
A4: Gastos de venta | B4: ANTICIPO A PROVEEDORES
A5: Gastos financieros | B5: ASOCIACION NACIONAL DE TIENDAS DE AUTOSERVICIO Y DEPARTAMENTALES
A6: Gasto logistica | B6: CARGO NO IDENTIFICADO
A7: Reembolsos | B7: CASETAS
A8: Gastos de almacenaje | B8: COMISIONES BANCARIAS
A9: Viaticos Expo Pan WTC | B9: COMISIONES EUROFORNO
A10: Otros gastos operativos | B10: COMISIONES SOBRE VENTAS
A11: ANTICIPO A PROVEEDORES | B11: COMISIONES VENDEDORES
A12: CARGOS NO RECONOCIDOS BBVA | B12: CONSULTORIA ANA GPT
... A16: Gastos de Viaje y Transportacion | B16: EQUIPO DE PROTECCION PERSONAL
B17: EQUIPO PARA VENDEDORES (CARGADOR, USB,PILAS)
B18: ESTACIONAMIENTOS
B19: EXPO FOOD SERVICE DE MEXICO
B20: FERRETERIA Y HERRAMIENTAS PARA BODEGA TOLUCA
B21: GASOLINA FABIO
B22: GASTOS VARIOS
B23: GASTOS VARIOS (FABIO)
B24: HERRERIA BODEGA TOLUCA
B25: IMPUESTOS ANUALES
B26: IMPUESTOS FEDERALES
B27: IMPUESTOS ISR RET
B28: IMPUESTOS IVA RET
... B97: PUBLICIDAD DIGITAL MANTTO PAG. INTERNET-QUITO, ECUADOR
