Workbook

Sheet Oct'24
A1: Estado de Resultados 2024
A2: Concepto | B2: 45566 | C2: %
A3: Ventas Netas | B3: =+'Ventas Oct´24'!G10 -> 20077000 | C3: 1
A4: Descuentos Realizados | B4: =+'Ventas Oct´24'!H10 -> 1576600 | C4: =(B4*C3)/B3 -> 0.078527668
A5: Total Ingresos | B5: =B3-B4 -> 18500400 | C5: 1
A6: Costo total | B6: =+'Ventas Oct´24'!V10 -> 6789547.2 | C6: 0.33
A7: Utilidad Marginal | B7: =B5-B6 -> 11710853 | C7: =(B7*C5)/B5 -> 0.63300538
A10: GASTOS VARIABLES | B10: =SUM(B11:B20) -> 7955875.3 | C10: =(B10*$C5)/$B5 -> 0.43003801
A11: COMISIONES BANCARIAS | B11: =+Gastos!C5 -> 54116.27 | C11: =(B11*$C$5)/$B$5 -> 0.0029251405
A12: COMISIONES DISTRIBUIDORES | B12: 0 | C12: =(B12*$C$5)/$B$5 -> 0
A13: COMISIONES VENTAS | B13: 0 | C13: =(B13*$C$5)/$B$5 -> 0
A14: ESTAFA | PAYWAY | B14: =+Gastos!C8 -> 6385235.3 | C14: =(B14*$C$5)/$B$5 -> 0.34514039
A15: EXTRAORDINARIOS | B15: =+Gastos!C10 -> 39023 | C15: =(B15*$C$5)/$B$5 -> 0.0021093057
A16: FLETES | B16: =+Gastos!C12 -> 164000 | C16: =(B16*$C$5)/$B$5 -> 0.0088646732
A17: IMPUESTOS | B17: =+Gastos!C59 -> 546012.87 | C17: =(B17*$C$5)/$B$5 -> 0.029513571
A18: MARKETING | B18: =+Gastos!C75 -> 168057 | C18: =(B18*$C$5)/$B$5 -> 0.0090839658
A19: PUESTA EN MARCHA | B19: 0 | C19: =(B19*$C$5)/$B$5 -> 0
A20: SIN IDENTIFICAR | B20: =+Gastos!C79 -> 599430.86 | C20: =(B20*$C$5)/$B$5 -> 0.032400968
A22: GASTOS FIJOS | B22: =SUM(B23:B24) -> 7014037.5 | C22: =(B22*$C5)/$B5 -> 0.37912896
A23: LOCAL | B23: =+Gastos!C71 -> 2955232.7 | C23: =(B23*$C$5)/$B$5 -> 0.15973885
A24: SUELDOS | B24: =+Gastos!C86 -> 4058804.8 | C24: =(B24*$C$5)/$B$5 -> 0.21939011
A26: GASTOS TOTALES | B26: =+B10+B22 -> 14969913
A28: UTILIDAD NETA | B28: =B7-B10-B22 -> -3259060 | C28: =(B28*C5)/B5 -> -0.1761616
A31: INVERSIONES (Certificaciones) | B31: =+Gastos!C91 -> 2410800

Sheet Gastos
A1: Fecha | B1: Descripción | C1: Retiros Débito | D1: Categoría | E1: SubCategoría
A2: 45581 | B2: COM.TRANS.INTERNET | C2: 3810 | D2: Comisiones Bancarias | E2: Comisiones Bancarias
A3: 45594 | B3: TARJ.CRED.(AJUSTE COM) | C3: 6.27 | D3: Comisiones Bancarias | E3: Comisiones Bancarias
A4: 45596 | B4: COMISION MANT.CTA | C4: 50300 | D4: Comisiones Bancarias | E4: Comisiones Bancarias
B5: =+D4 -> Comisiones Bancarias | C5: =SUM(C2:C4) -> 54116.27
A6: 45581 | B6: TARJ.CRED.(AJUSTE COM) | C6: 1032941.8 | D6: Estafa | E6: Payway
A7: 45588 | B7: TARJ.CRED.(AJUSTE COM) | C7: 5352293.4 | D7: Estafa
B8: =+D6 -> Estafa | C8: =SUM(C6:C7) -> 6385235.3
A9: 45588 | B9: INSTRUCCION DE PAGO | C9: 39023 | D9: Extraordinarios | E9: Enchufe
B10: =+D9 -> Extraordinarios | C10: =+C9 -> 39023
A11: 45582 | B11: TRASNF. ELECTRONICA | C11: 164000 | D11: Flete | E11: Flete
B12: =+D11 -> Flete | C12: =+C11 -> 164000
A13: 45566 | B13: IMP. LEY 25.413 | C13: 9.05 | D13: Impuestos | E13: Ley 25.413
A14: 45566 | B14: IMP. LEY 25.413 | C14: 9.05 | D14: Impuestos | E14: Ley 25.413
A15: 45566 | B15: IMP. LEY 25.413 | C15: 63.38 | D15: Impuestos | E15: Ley 25.413
A16: 45566 | B16: IMP. LEY 25.413 | C16: 300 | D16: Impuestos | E16: Ley 25.413
A17: 45566 | B17: IMP. LEY 25.413 | C17: 301.8 | D17: Impuestos | E17: Ley 25.413
A18: 45566 | B18: IMP. LEY 25.413 | C18: 6415.76 | D18: Impuestos | E18: Ley 25.413
A19: 45567 | B19: IMP. LEY 25.413 | C19: 191.24 | D19: Impuestos | E19: Ley 25.413
A20: 45569 | B20: IMP. LEY 25.413 | C20: 140.99 | D20: Impuestos | E20: Ley 25.413
A21: 45569 | B21: IMP. LEY 25.413 | C21: 2117.02 | D21: Impuestos | E21: Ley 25.413
A22: 45572 | B22: IMP. LEY 25.413 | C22: 660.6 | D22: Impuestos | E22: Ley 25.413
A23: 45572 | B23: IMP. LEY 25.413 | C23: 12000 | D23: Impuestos | E23: Ley 25.413
A24: 45572 | B24: IMP. LEY 25.413 | C24: 19275.82 | D24: Impuestos | E24: Ley 25.413
... A58: 45596 | B58: INGR.BRUTOS | C58: 1509 | D58: Impuestos | E58: Ingresos Brutos
B59: =+D58 -> Impuestos | C59: =SUM(C13:C58) -> 546012.87
A60: 45566 | B60: PROSEGUR PROS ALAR FACT 1201775879 | C60: 31872.96 | D60: Local | E60: Alarma Local
A61: 45568 | B61: DEBITO AUTOMATICO | C61: 23498.19 | D61: Local | E61: Teléfonos
A62: 45574 | B62: INSTRUCCION DE PAGO | C62: 226700 | D62: Local | E62: Alquiler
A63: 45575 | B63: SOLUCIONES ONLINE SA | C63: 96316 | D63: Local | E63: Sistema Gestión | Xubio
A64: 45586 | B64: PAGO SERVICIOS ENOR | C64: 279797.54 | D64: Local | E64: Edenor
A65: 45586 | B65: INSTRUCCION DE PAGO | C65: 350000 | D65: Local | E65: Honorarios Contables
B66: ALQUILER OCT | C66: 800000 | D66: Local | E66: ALQUILER
A67: 45952 | B67: reposición caja chica | C67: 50048 | D67: Local | E67: CAJA CHICA
A68: 45953 | B68: desasolve cloaca | C68: 105000 | D68: Local | E68: DESTAPACION CLOCA
A69: 45960 | B69: anticipo macetas | C69: 100000 | D69: Local | E69: MANTENIMIENTO
A70: 45961 | B70: carpintero | C70: 892000 | D70: Local | E70: MANTENIMIENTO
B71: =+D70 -> Local | C71: =SUM(C60:C70) -> 2955232.7
A72: 45574 | B72: INSTRUCCION DE PAGO | C72: 82038 | D72: Marketing | E72: Tarjetas Personales
A73: 45583 | B73: INSTRUCCION DE PAGO | C73: 41019 | D73: Marketing | E73: Tarjetas Personales
...

Sheet Ventas Oct´24
A1: OPERADOR | B1: FECHA | C1: PRODUCTO | D1: nº de serie | E1: DESPACHO N° | F1: CLIENTE | G1: Valor Lista | H1: Dto.% | I1: Valor Cotizado sin iva | J1: MONTO NETO | K1: IVA | L1: Tipo de IVA | M1: MONTO TOTAL | N1: Valor TOTAL Cotización CON IVA | O1: HSBC | P1: efectivo / morva | Q1: total pagado | R1: por cobrar | S1: FACTURADO | T1: CUIT | U1: Forma de Pago | V1: Costo Contable
A2: Javier | B2: 45568 | C2: FN2 PRO | D2: 202403595 | E2: 24 001 IC04 0985888 X | F2: Javier Morano/Soface 3,10 | G2: 2010000 | H2: 0.35 | I2: =+G2-(G2*H2) -> 1306500 | J2: 653250 | K2: 137182.5 | L2: 0.21 | M2: 790432.5 | N2: 1443682.5 | P2: 2000000 | Q2: 2000000 | R2: -556317.5 | S2: Factura A -32 | T2: 30-6566-1936-4 | U2: Efectivo | V2: =460.09*1033.5 -> 475503.01
A3: Javier | C3: PRO HOUSE | E3: 24 001 IC04 0985888 X | F3: Javier Morano/Black Iron | G3: 1080000 | H3: 0.1 | I3: =+G3-(G3*H3) -> 972000 | J3: 972000 | K3: 102060 | L3: 0.105 | M3: 1074060 | N3: 1074060 | O3: 1074060 | Q3: 1074060 | R3: 0 | T3: 30-71852393-8 | U3: Transferencia | V3: =251.5*1033.5 -> 259925.25
A4: Javier | C4: Pala | E4: 24 001 IC04 0985888 X | F4: Javier Morano/Black Iron | G4: 91000 | H4: 0.1 | I4: =+G4-(G4*H4) -> 81900 | J4: 81900 | K4: 17199 | L4: 0.21 | M4: 99099 | N4: 99099 | O4: 99099 | Q4: 99099 | R4: 0 | T4: 30-71852393-8 | U4: Transferencia | V4: =28.64*1033.5 -> 29599.44
A5: Cynthia | B5: 45572 | C5: Pala | E5: 24 001 IC04 0985888 X | F5: Rodríguez y Parise, SRL. | G5: 91000 | H5: 0 | I5: =+G5-(G5*H5) -> 91000 | J5: 91000 | K5: 19110 | L5: 0.21 | M5: 110110 | N5: 110110 | O5: 110110 | Q5: 110110 | R5: 0 | S5: Factura A -33 | T5: 30-71081767-3 | U5: Hsbc | V5: =28.64*1033.5 -> 29599.44
A6: Cynthia | B6: 45583 | C6: PRO GAS 106 | D6: G24038032010 | E6: 24 001 IC04 0985888 X | F6: VICTOR CENDRA | G6: 3210000 | H6: 0.1 | I6: =+G6-(G6*H6) -> 2889000 | J6: 2889000 | K6: 303345 | L6: 0.105 | M6: 3192345 | N6: 3192345 | P6: 3192345 | Q6: 3192345 | R6: 0 | S6: No pide factura | T6: 20-26865743-7 | U6: Efectivo | V6: =1056.16*1033.5 -> 1091541.4
A7: Cynthia | B7: 45583 | C7: PRO GAS 106 | D7: G24038032014 | E7: 24 001 IC04 0985888 X | F7: TRICAN S.A.S. / LEO LOPEZ | G7: 3210000 | H7: 0 | I7: =+G7-(G7*H7) -> 3210000 | J7: 3210000 | K7: 337050 | L7: 0.105 | M7: 3547050 | N7: 3547050 | O7: 3547050 | Q7: 3547050 | R7: 0 | S7: Factura A -35 | T7: 30-71696818-5 | U7: Hsbc | V7: =1056.16*1033.5 -> 1091541.4
A8: Cynthia | B8: 45583 | C8: Mantecadora | D8: No tiene número de serie | E8: 24 001 IC04 0985888 X | F8: Alejandro Martin Lemmo | G8: 6035000 | H8: 0 | I8: =+G8-(G8*H8) -> 6035000 | J8: 2112250 | K8: 443572.5 | L8: 0.21 | M8: 2555822.5 | N8: 6478572.5 | O8: 2555822.5 | P8: 3922750 | Q8: 6478572.5 | R8: 0 | T8: 20-29125198-7 | U8: Hsbc/Morva | V8: =2686.73*1033.5 -> 2776735.5
A9: Cynthia | B9: 45594 | C9: Pro gas 90 | D9: GS24038032008 | E9: 24 001 IC04 0985888 X | F9: Marcelo Marino | G9: 4350000 | H9: 0.1 | I9: =+G9-(G9*H9) -> 3915000 | J9: 3915000 | K9: 411075 | L9: 0.105 | M9: 4326075 | N9: 4326075 | O9: 2326075 | P9: 2000000 | Q9: 4326075 | R9: 0 | S9: Factura A-36 | T9: 20-22994203-5 | U9: Hsbc/Morva/Efectivo | V9: =1001.55*1033.5 -> 1035101.9
B10: TOTALES | G10: =SUM(G2:G9) -> 20077000 | H10: =+G10-I10 -> 1576600 | I10: =SUM(I2:I9) -> 18500400 | J10: =SUM(J2:J9) -> 13924400 | K10: =SUM(K2:K9) -> 1770594 | L10: =SUM(L2:L9) -> 1.26 | M10: =SUM(M2:M9) -> 15694994 | N10: =SUM(N2:N9) -> 20270994 | O10: =SUM(O2:O9) -> 9712216.5 | P10: =SUM(P2:P9) -> 11115095 | ... V10: =SUM(V2:V9) -> 6789547.2

Sheet LISTA CONCEPTOS
A1: CUENTA | B1: SUBCUENTA
A2: Gasto de nómina | B2: ADQUISICION DE MERCANCIAS
A3: Gastos por servicios | B3: ALMACEN IFULL
A4: Gastos de venta | B4: ANTICIPO A PROVEEDORES
A5: Gastos financieros | B5: ASOCIACION NACIONAL DE TIENDAS DE AUTOSERVICIO Y DEPARTAMENTALES
A6: Gasto logistica | B6: CARGO NO IDENTIFICADO
A7: Reembolsos | B7: CASETAS
A8: Gastos de almacenaje | B8: COMISIONES BANCARIAS
A9: Viaticos Expo Pan WTC | B9: COMISIONES EUROFORNO
A10: Otros gastos operativos | B10: COMISIONES SOBRE VENTAS
A11: ANTICIPO A PROVEEDORES | B11: COMISIONES VENDEDORES
A12: CARGOS NO RECONOCIDOS BBVA | B12: CONSULTORIA ANA GPT
... A16: Gastos de Viaje y Transportacion | B16: EQUIPO DE PROTECCION PERSONAL
B17: EQUIPO PARA VENDEDORES (CARGADOR, USB,PILAS)
B18: ESTACIONAMIENTOS
B19: EXPO FOOD SERVICE DE MEXICO
B20: FERRETERIA Y HERRAMIENTAS PARA BODEGA TOLUCA
B21: GASOLINA FABIO
B22: GASTOS VARIOS
B23: GASTOS VARIOS (FABIO)
B24: HERRERIA BODEGA TOLUCA
B25: IMPUESTOS ANUALES
B26: IMPUESTOS FEDERALES
B27: IMPUESTOS ISR RET
B28: IMPUESTOS IVA RET
... B97: PUBLICIDAD DIGITAL MANTTO PAG. INTERNET-QUITO, ECUADOR
