Workbook

Sheet Nov'24
A1: Estado de Resultados 2024
A2: Concepto | B2: 45597 | C2: %
A3: Ventas Netas | B3: =+'Ventas Nov´24'!H6 -> 10716000 | C3: 1
A4: Descuentos Realizados | B4: =+'Ventas Nov´24'!I6 -> 481500 | C4: =(B4*C3)/B3 -> 0.044932811
A5: Total Ingresos | B5: =B3-B4 -> 10234500 | C5: 1
A6: Costo total | B6: =+'Ventas Nov´24'!P6 -> 3208035.7 | C6: 0.33
A7: Utilidad Marginal | B7: =B5-B6 -> 7026464.3 | C7: =(B7*C5)/B5 -> 0.68654691
A10: GASTOS VARIABLES | B10: =SUM(B11:B19) -> 4282476.3 | C10: =(B10*$C5)/$B5 -> 0.41843532
A11: COMISIONES BANCARIAS | B11: =+Gastos!D5 -> 80338.56 | C11: =(B11*$C$5)/$B$5 -> 0.0078497787
A12: COMISIONES DISTRIBUIDORES | B12: 0 | C12: =(B12*$C$5)/$B$5 -> 0
A13: COMISIONES VENTAS | B13: 0 | C13: =(B13*$C$5)/$B$5 -> 0
A14: ESTAFA | PAYWAY | B14: =+Gastos!D7 -> 3276676.4 | C14: =(B14*$C$5)/$B$5 -> 0.32015989
A15: EXTRAORDINARIOS | B15: =+Gastos!D9 -> 181500 | C15: =(B15*$C$5)/$B$5 -> 0.017734135
A16: FLETES | B16: 0 | C16: =(B16*$C$5)/$B$5 -> 0
A17: IMPUESTOS | B17: =+Gastos!D83 -> 655923.38 | C17: =(B17*$C$5)/$B$5 -> 0.064089441
A18: MARKETING | B18: =+Gastos!D100 -> 88038 | C18: =(B18*$C$5)/$B$5 -> 0.0086020812
A19: PUESTA EN MARCHA | B19: 0 | C19: =(B19*$C$5)/$B$5 -> 0
A21: GASTOS FIJOS | B21: =SUM(B22:B23) -> 6518266.4 | C21: =(B21*$C5)/$B5 -> 0.63689153
A22: LOCAL | B22: =+Gastos!D97 -> 2265230.6 | C22: =(B22*$C$5)/$B$5 -> 0.2213328
A23: SUELDOS | B23: =+Gastos!D111 -> 4253035.8 | C23: =(B23*$C$5)/$B$5 -> 0.41555873
A25: GASTOS TOTALES | B25: =+B10+B21 -> 10800743
A27: UTILIDAD NETA | B27: =B7-B10-B21 -> -3774278.4 | C27: =(B27*C5)/B5 -> -0.36877995
A30: INVERSIONES (Certificaciones) | B30: =+Gastos!D120 -> 2578347.5

Sheet Gastos
A1: Fecha | B1: Descripción | C1: Retiros Débito | D1: Rubro | E1: Categoría | F1: SubCategoría
A2: 45601 | B2: TARJ.CRED.(AJUSTE COM) | D2: 24958.56 | E2: Comisiones Bancarias | F2: PAYWAY
A3: 45621 | B3: COM.TRANSF.INTERNET | D3: 5080 | E3: Comisiones Bancarias | F3: Comisiones Bancarias
A4: 45625 | B4: COMISION MANT.CTA | D4: 50300 | E4: Comisiones Bancarias | F4: Comsiones Bancarias
B5: =+E4 -> Comisiones Bancarias | D5: =SUM(D2:D4) -> 80338.56
A6: 45597 | B6: TARJ.CRED.(AJUSTE COM) | D6: 3276676.4 | E6: Estafa | F6: PAYWAY | Total $3.400.000.- | Estafa
B7: =+E6 -> Estafa | D7: =SUM(D6) -> 3276676.4
A8: 45611 | B8: INSTRUCCION DE PAGO MOL Y BAND S.A | D8: 181500 | E8: Extraordinarias | F8: Mesa p/horno
B9: =+E8 -> Extraordinarias | D9: =SUM(D8) -> 181500
A10: 45597 | B10: IMP. LEY 25.413 | D10: 9.05 | E10: Impuestos | F10: Ley 25.413
A11: 45597 | B11: IMP. LEY 25.413 | D11: 9.05 | E11: Impuestos | F11: Ley 25.413
A12: 45597 | B12: IMP. LEY 25.413 | D12: 63.38 | E12: Impuestos | F12: Ley 25.413
A13: 45597 | B13: IMP. LEY 25.413 | D13: 301.8 | E13: Impuestos | F13: Ley 25.413
A14: 45597 | B14: IMP. LEY 25.413 | D14: 1950.95 | E14: Impuestos | F14: Ley 25.413
A15: 45597 | B15: IMP. LEY 25.413 | D15: 2926.42 | E15: Impuestos | F15: Ley 25.413
A16: 45600 | B16: IMP. LEY 25.413 | D16: 206.54 | E16: Impuestos | F16: Ley 25.413
A17: 45600 | B17: IMP. LEY 25.413 | D17: 1950.95 | E17: Impuestos | F17: Ley 25.413
A18: 45600 | B18: REG.REC.SIRCREB | D18: 3901.9 | E18: Impuestos | F18: Sircreb
A19: 45600 | B19: IMP. LEY 25.413 | D19: 19660.06 | E19: Impuestos | F19: Ley 25.413
A20: 45601 | B20: IMP. LEY 25.413 | D20: 23.41 | E20: Impuestos | F20: Ley 25.413
A21: 45601 | B21: IMP. LEY 25.413 | D21: 2749.35 | E21: Impuestos | F21: Ley 25.413
... A82: 45625 | B82: INGRESOS BRUTOS | D82: 1509 | E82: Impuestos | F82: INGRESOS BRUTOS PERCEPCION
B83: =+E82 -> Impuestos | D83: =SUM(D10:D82) -> 655923.38
A84: 45597 | B84: DEBITO AUTOMATICO / PROSEGUR | D84: 34422.8 | E84: Local | F84: Alarma Prosegur
A85: 45601 | B85: DEBITO AUTOMATICO | D85: 24431.64 | E85: Local | F85: Teléfonos fc 4618390
A86: 45607 | B86: TELECOMARGENTINA PERSONAL CLIENTE: 1031314103 | D86: 180666.64 | E86: Local | F86: Internet
A87: 45611 | B87: INSTRUCCION DE PAGO | D87: 175891.17 | E87: Local | F87: Manija + Boca Llave
A88: 45611 | B88: INSTRUCCION DE PAGO | D88: 251090 | E88: Local | F88: ALQUILER
A89: 45611 | B89: SOLUCIONES ONLIN SOL.ONLINE CLIENTE: 1500072500032232871914 | D89: 99704 | E89: Local | F89: Sistema de Gestión | Xubio fc 383090
A90: 45617 | B90: INSTRUCCION DE PAGO | D90: 200000 | E90: Local | F90: HONORARIOS CONTABLES
A91: 45624 | B91: SERVICIO: ENOR IDENTIFICACION: 000408109794 | D91: 328127.34 | E91: Local | F91: EDENOR
B92: ALQUILER NOV | D92: 800000 | E92: Local | F92: ALQUILER
B93: Celular para el CRM de Argentina | D93: 64997 | E93: Local | F93: CELULAR
A94: 45976 | B94: Alquiler diferencia efectivo por inflación | D94: 70000 | E94: Local | F94: ALQUILER
A95: 45976 | B95: Agua local balbin | D95: 22400 | E95: Local | F95: AYSA | AGUA
A96: 45980 | B96: Diego le pago a Lorena, MAESTRANZA | D96: 13500 | E96: Local | F96: LIMPIEZA LOCAL
B97: =+E96 -> Local | D97: =SUM(D84:D96) -> 2265230.6
A98: 45624 | B98: JM Imprenta | Karina Martino | Fc 9481 | D98: 47019 | E98: Marketing | F98: Tarjetas Personales | Carolina
A99: 45988 | B99: 200 TARJETAS PERSONALES 4/4 FULL COLO | Carolina | D99: 41019 | E99: Marketing | F99: TARJETAS PERSONALES
B100: =+E99 -> Marketing | D100: =SUM(D98:D99) -> 88038
...

Sheet Ventas Nov´24
A1: Operador | B1: Fecha | C1: Cliente | D1: Producto | E1: Nº Serie | F1: N° Despacho | G1: # | H1: Valor Unitario | I1: Dto % | J1: VALOR COTIZADO | K1: Facturado | L1: Tipo de IVA | M1: IVA | N1: Monto con IVA | O1: MONTO TOTAL | P1: Costo Contable
A2: Cynthia | B2: 45603 | C2: Franco David Argañaraz | D2: PRO GAS 106 | E2: G24038032003 | F2: 24 001 IC04 0985888 X | G2: 1 | H2: 3210000 | I2: 0.05 | J2: =+H2-(H2*I2) -> 3049500 | K2: 1524750 | L2: 0.105 | M2: =+K2*L2 -> 160098.75 | N2: =+K2+M2 -> 1684848.8 | O2: =+J2+M2 -> 3209598.8 | P2: =1056.16*1033.5 -> 1091541.4
A3: Lelia | B3: 45610 | C3: TANIA MARION | D3: PRO ELECTRICO 90 + PALA | E3: S240380320004 | F3: 24 001 IC04 0985888 X | G3: 1 | H3: =3125000+91000 -> 3216000 | I3: 0 | J3: =+H3-(H3*I3) -> 3216000 | K3: 3216000 | L3: 0.21 | M3: =+K3*L3 -> 675360 | N3: =+K3+M3 -> 3891360 | O3: =+J3+M3 -> 3891360 | P3: =(716.03+28.64)*1033.5 -> 769616.44
A4: Cynthia | B4: 45597 | C4: SUSANA LACTEOS CABANELA | D4: FN1 PRO | E4: 202410312 | F4: 24 001 IC04 0985888 X | G4: 1 | H4: 1080000 | I4: 0 | J4: =+H4-(H4*I4) -> 1080000 | K4: 1080000 | L4: 0.21 | M4: =+K4*L4 -> 226800 | N4: =+K4+M4 -> 1306800 | O4: =+J4+M4 -> 1306800 | P4: =247.06*1033.5 -> 255336.51
A5: Javier | B5: 45597 | C5: WALTER MASSITA | D5: PRO GAS 106 | E5: G24038032013 | F5: 24 001 IC04 0985888 X | G5: 1 | H5: 3210000 | I5: 0.1 | J5: =+H5-(H5*I5) -> 2889000 | K5: 2889000 | L5: 0.105 | M5: =+K5*L5 -> 303345 | N5: =+K5+M5 -> 3192345 | O5: =+J5+M5 -> 3192345 | P5: =1056.16*1033.5 -> 1091541.4
H6: =SUM(H2:H5) -> 10716000 | I6: =+H6-J6 -> 481500 | J6: =SUM(J2:J5) -> 10234500 | P6: =SUM(P2:P5) -> 3208035.7

Sheet LISTA CONCEPTOS
A1: CUENTA | B1: SUBCUENTA
A2: Gasto de nómina | B2: ADQUISICION DE MERCANCIAS
A3: Gastos por servicios | B3: ALMACEN IFULL
A4: Gastos de venta | B4: ANTICIPO A PROVEEDORES
A5: Gastos financieros | B5: ASOCIACION NACIONAL DE TIENDAS DE AUTOSERVICIO Y DEPARTAMENTALES
A6: Gasto logistica | B6: CARGO NO IDENTIFICADO
A7: Reembolsos | B7: CASETAS
A8: Gastos de almacenaje | B8: COMISIONES BANCARIAS
A9: Viaticos Expo Pan WTC | B9: COMISIONES EUROFORNO
A10: Otros gastos operativos | B10: COMISIONES SOBRE VENTAS
A11: ANTICIPO A PROVEEDORES | B11: COMISIONES VENDEDORES
A12: CARGOS NO RECONOCIDOS BBVA | B12: CONSULTORIA ANA GPT
... A16: Gastos de Viaje y Transportacion | B16: EQUIPO DE PROTECCION PERSONAL
B17: EQUIPO PARA VENDEDORES (CARGADOR, USB,PILAS)
B18: ESTACIONAMIENTOS
B19: EXPO FOOD SERVICE DE MEXICO
B20: FERRETERIA Y HERRAMIENTAS PARA BODEGA TOLUCA
B21: GASOLINA FABIO
B22: GASTOS VARIOS
B23: GASTOS VARIOS (FABIO)
B24: HERRERIA BODEGA TOLUCA
B25: IMPUESTOS ANUALES
B26: IMPUESTOS FEDERALES
B27: IMPUESTOS ISR RET
B28: IMPUESTOS IVA RET
... B97: PUBLICIDAD DIGITAL MANTTO PAG. INTERNET-QUITO, ECUADOR
