Workbook

Sheet Jul'24
A1: Estado de Resultados 2024
A2: Concepto | B2: 45474 | C2: %
A3: Ventas Netas | B3: =+'Ventas Jul´24'!G10 -> 22170000 | C3: 1
A4: Descuentos Realizados | B4: =+'Ventas Jul´24'!H10 -> 431500 | C4: =(B4*C3)/B3 -> 0.019463239
A5: Total Ingresos | B5: =B3-B4 -> 21738500 | C5: 1
A6: Costo total | B6: =+'Ventas Jul´24'!J10 -> 4571583.9 | C6: 0.33
A7: Utilidad Marginal | B7: =B5-B6 -> 17166916 | C7: =(B7*C5)/B5 -> 0.78970104
A10: GASTOS VARIABLES | B10: =SUM(B11:B19) -> 5071229.2 | C10: =(B10*$C5)/$B5 -> 0.23328331
A11: COMISIONES BANCARIAS | B11: =+Gastos!C5 -> 73203.54 | C11: =(B11*$C$5)/$B$5 -> 0.0033674605
A12: COMISIONES DISTRIBUIDORES | B12: 0 | C12: =(B12*$C$5)/$B$5 -> 0
A13: COMISIONES VENTAS | B13: 0 | C13: =(B13*$C$5)/$B$5 -> 0
A14: EXTRAORDINARIOS | B14: 0 | C14: =(B14*$C$5)/$B$5 -> 0
A15: FLETES | B15: =+Gastos!C8 -> 108000 | C15: =(B15*$C$5)/$B$5 -> 0.0049681441
A16: IMPUESTOS | B16: =+Gastos!C69 -> 1025927.1 | C16: =(B16*$C$5)/$B$5 -> 0.047194013
A17: MARKETING | B17: =+Gastos!C85 -> 340529.82 | C17: =(B17*$C$5)/$B$5 -> 0.015664826
A18: PUESTA EN MARCHA | B18: 0 | C18: =(B18*$C$5)/$B$5 -> 0
A19: SIN IDENTIFICAR | B19: =+Gastos!C91 -> 3523568.8 | C19: =(B19*$C$5)/$B$5 -> 0.16208887
A21: GASTOS FIJOS | B21: =SUM(B22:B23) -> 2706666.8 | C21: =(B21*$C5)/$B5 -> 0.12451028
A22: LOCAL | B22: =+Gastos!C79 -> 1906666.8 | C22: =(B22*$C$5)/$B$5 -> 0.087709215
A23: SUELDOS | B23: =+Gastos!C94 -> 800000 | C23: =(B23*$C$5)/$B$5 -> 0.036801067
A25: GASTOS TOTALES | B25: =+B10+B21 -> 7777896
A27: UTILIDAD NETA | B27: =B7-B10-B21 -> 9389020.1 | C27: =(B27*C5)/B5 -> 0.43190745
A30: INVERSIONES | B30: =+Gastos!C96 -> 847000

Sheet Gastos
A1: Fecha | B1: Descripción | C1: Retiros Débito | D1: Categoría | E1: SubCategoría
A2: 45475 | B2: AJUSTE TARJETA DEBITO 0056 TARJ. CRED. (AJUSTE COM) | C2: 4748 | D2: Comisiones Bancarias | E2: PayWay
A3: 45503 | B3: TARJ CRED. AJUSTE COM TARJ CRED.(AJUSTE COM) | C3: 26155.54 | D3: Comisiones Bancarias | E3: PayWay
A4: 45504 | B4: COMISION MANT. CTA | C4: 42300 | D4: Comisiones Bancarias | E4: Comisiones Bancarias
B5: =+D4 -> Comisiones Bancarias | C5: =SUM(C2:C4) -> 73203.54
A6: 45485 | B6: flete hornos | C6: 48000 | D6: Flete | E6: Flete
A7: 45504 | B7: flete | C7: 60000 | D7: Flete | E7: Flete
B8: =+D7 -> Flete | C8: =SUM(C6:C7) -> 108000
A9: 45474 | B9: IMP. LEY 25.413 BASE: | C9: 900 | D9: Impuestos | E9: Ley 25.413
A10: 45474 | B10: IMP. LEY 25.413 BASE: | C10: 4830 | D10: Impuestos | E10: Ley 25.413
A11: 45474 | B11: IMP. LEY 25.413 BASE: | C11: 30000 | D11: Impuestos | E11: Ley 25.413
A12: 45474 | B12: IMP. LEY 25.413 BASE: | C12: 64800 | D12: Impuestos | E12: Ley 25.413
A13: 45475 | B13: IMP. EXTERIOR 01230 REF. 24001IC04098482B | C13: 860.92 | D13: Impuestos | E13: Importación
A14: 45475 | B14: IMP. EXTERIOR 01246 REF. 24001IC04098588X | C14: 860.92 | D14: Impuestos | E14: Importación
A15: 45475 | B15: IMP. EXTERIOR 01229 REF. 24001IC04098482B | C15: 6026.45 | D15: Impuestos | E15: Importación
A16: 45475 | B16: IMP. EXTERIOR 01245 REF. 24001IC04098588X | C16: 6026.45 | D16: Impuestos | E16: Importación
A17: 45475 | B17: IMP. EXTERIOR 01231 REF. 24001IC04098482B | C17: 28697.4 | D17: Impuestos | E17: Importación
A18: 45475 | B18: IMP. EXTERIOR 01247 REF. 24001IC04098588X | C18: 28697.4 | D18: Impuestos | E18: Importación
A19: 45475 | B19: IMP. LEY 25.413 BASE: | C19: 170.75 | D19: Impuestos | E19: Ley 25.413
A20: 45475 | B20: IMP. LEY 25.413 BASE: | C20: 210 | D20: Impuestos | E20: Ley 25.413
... A68: 45504 | B68: 2165 INGRESOS BRUTOS | C68: 1269 | D68: Impuestos | E68: Ingresos Brutos
B69: =+D68 -> Impuestos | C69: =SUM(C9:C68) -> 1025927.1
A70: 45474 | B70: PAGO 070004103 PROSEGUR CLIENTE 546521 | C70: 28458 | D70: Local | E70: Alarma Local
A71: 45476 | B71: TARJETA DEBITO 0700002875 DEBITO AUTOM- CABLEVISION | C71: 40608.76 | D71: Local | E71: Teléfonos
A72: 45481 | B72: PAGO 0051418204 INSTRUCCIÓN DE PAGO | C72: 200000 | D72: Local | E72: Alquiler
A73: 45499 | B73: PAGO 0051775602 INSTRUCCIÓN DE PAGO | C73: 70000 | D73: Local | E73: Honorarios Contables
A74: 45499 | B74: PAGO 1151775589 INSTRUCCIÓN DE PAGO | C74: 150000 | D74: Local | E74: Honorarios Contables
A75: 45482 | B75: renta julio | C75: 350000 | D75: Local | E75: ALQUILER
A76: 45482 | B76: renta julio | C76: 350000 | D76: Local | E76: ALQUILER
A77: 45499 | B77: alquiler agosto | C77: 700000 | D77: Local | E77: ALQUILER
A78: 45499 | B78: agua del local | C78: 17600 | D78: Local | E78: AYSA (AGUA LOCAL)
B79: =+D78 -> Local | C79: =SUM(C70:C78) -> 1906666.8
A80: 45477 | B80: PAGO LA HOLANDO SUDAM SEGUROS FACT AP 5957185 010 | C80: 11847.56 | D80: Marketing | E80: Seguro Stand y Personal Expo?
A81: 45477 | B81: PAGO LA HOLANDO SUDAM SEGUROS FACT AP 5957185 010 | C81: 32900.7 | D81: Marketing | E81: Seguro Stand y Personal Expo?
A82: 45477 | B82: PAGO LA HOLANDO SUDAM SEGUROS FACT RC 1077328 000 | C82: 84581.56 | D82: Marketing | E82: Seguro Stand y Personal Expo?
A83: 45329 | B83: CENA FABIO Y JAVIER HAPENNING | C83: 131200 | D83: Marketing | E83: GASTOS REPRESENTACION
A84: 45504 | B84: comida con diego apyce | C84: 80000 | D84: Marketing | E84: GASTOS REPRESENTACION
B85: =+D84 -> Marketing | C85: =SUM(C80:C84) -> 340529.82
A86: 45476 | B86: 005698 0012 TRANSF. ELECTRONICA | C86: 105000 | D86: SIN IDENTIFICAR
A87: 45477 | B87: TRANSF ELEC. 09861 TRANSF. ELECTRÓNICA | C87: 250000 | D87: SIN IDENTIFICAR
...

Sheet Ventas Jul´24
A1: Fecha | B1: Vendedor | C1: Cant | D1: Producto | E1: Nro de serie | F1: Nombre cliente | G1: Precio Lista | H1: Dto. % | I1: Precio Cotizado | J1: Costo Contable
A2: 45835 | B2: Ariel | C2: 2 | D2: FN1 PRO | E2: 202403580 y 202403583 | F2: Tomasso- Matias/PIZZAS AL VACIO | G2: 1940000 | H2: 0.1 | I2: =+G2-(G2*H2) -> 1746000 | J2: =247.06*1033.5 -> 255336.51
A3: 45848 | B3: Javier | C3: 1 | D3: PRO ELÉCTRICO 90 | E3: GS240380320002 | F3: Ortigoza- Misiones/MARIO FABIAN | G3: 2810000 | H3: 0.05 | I3: =+G3-(G3*H3) -> 2669500 | J3: =716.03*1033.5 -> 740017.01
A4: 45848 | B4: Javier | C4: 1 | D4: FN1 PRO | E4: 202403579 | F4: Fragor SRL- MIsiones | G4: 970000 | H4: 0.05 | I4: =+G4-(G4*H4) -> 921500 | J4: =247.06*1033.5 -> 255336.51
A5: 45853 | B5: ariel | C5: 1 | D5: PRO GAS 90 | E5: GS24038032007 | F5: Nicolas Zanet/ROMINA SOLEDAD | G5: 3900000 | H5: 0 | I5: =+G5-(G5*H5) -> 3900000 | J5: =1001.55*1033.5 -> 1035101.9
A6: 45860 | B6: Javier | C6: 1 | D6: FN1 PRO | E6: 202403577 | F6: Federico de Bella | G6: 970000 | H6: 0.05 | I6: =+G6-(G6*H6) -> 921500 | J6: =247.06*1033.5 -> 255336.51
A7: 45860 | B7: Ariel | C7: 1 | D7: PRO ELÉCTRICO 90 | E7: ES240380320010 | F7: Baguette del sol Srl | G7: 2810000 | H7: 0 | I7: =+G7-(G7*H7) -> 2810000 | J7: =716.03*1033.5 -> 740017.01
A8: 45862 | B8: Ariel | C8: 1 | D8: FN1 PRO | E8: 2024 035087 | F8: Mauro Nicolosi | G8: 970000 | H8: 0 | I8: =+G8-(G8*H8) -> 970000 | J8: =247.06*1033.5 -> 255336.51
A9: 45862 | B9: Ariel | C9: 2 | D9: PRO GAS 90 | E9: 24038032003 y 24038032006 | F9: Lionel/LEE CONFITERIAS | G9: =3900000*C9 -> 7800000 | H9: 0 | I9: =+G9-(G9*H9) -> 7800000 | J9: =1001.55*1033.5 -> 1035101.9
G10: =SUM(G2:G9) -> 22170000 | H10: =+G10-I10 -> 431500 | I10: =SUM(I2:I9) -> 21738500 | J10: =SUM(J2:J9) -> 4571583.9

Sheet LISTA CONCEPTOS
A1: CUENTA | B1: SUBCUENTA
A2: Gasto de nómina | B2: ADQUISICION DE MERCANCIAS
A3: Gastos por servicios | B3: ALMACEN IFULL
A4: Gastos de venta | B4: ANTICIPO A PROVEEDORES
A5: Gastos financieros | B5: ASOCIACION NACIONAL DE TIENDAS DE AUTOSERVICIO Y DEPARTAMENTALES
A6: Gasto logistica | B6: CARGO NO IDENTIFICADO
A7: Reembolsos | B7: CASETAS
A8: Gastos de almacenaje | B8: COMISIONES BANCARIAS
A9: Viaticos Expo Pan WTC | B9: COMISIONES EUROFORNO
A10: Otros gastos operativos | B10: COMISIONES SOBRE VENTAS
A11: ANTICIPO A PROVEEDORES | B11: COMISIONES VENDEDORES
A12: CARGOS NO RECONOCIDOS BBVA | B12: CONSULTORIA ANA GPT
... A16: Gastos de Viaje y Transportacion | B16: EQUIPO DE PROTECCION PERSONAL
B17: EQUIPO PARA VENDEDORES (CARGADOR, USB,PILAS)
B18: ESTACIONAMIENTOS
B19: EXPO FOOD SERVICE DE MEXICO
B20: FERRETERIA Y HERRAMIENTAS PARA BODEGA TOLUCA
B21: GASOLINA FABIO
B22: GASTOS VARIOS
B23: GASTOS VARIOS (FABIO)
B24: HERRERIA BODEGA TOLUCA
B25: IMPUESTOS ANUALES
B26: IMPUESTOS FEDERALES
B27: IMPUESTOS ISR RET
B28: IMPUESTOS IVA RET
... B97: PUBLICIDAD DIGITAL MANTTO PAG. INTERNET-QUITO, ECUADOR
