Workbook

Sheet Ene´25
A1: Estado de Resultados 2025
A2: Concepto | B2: 45669 | C2: %
A3: Ventas Netas | B3: =+'Ventas Ene''24'!I14 -> 37599001 | C3: 1
A4: Descuentos Realizados | B4: =+'Ventas Ene''24'!J14 -> 2960198 | C4: =(B4*C3)/B3 -> 0.078730763
A5: Total Ingresos | B5: =B3-B4 -> 34638803 | C5: 1
A6: Costo total | B6: =+'Ventas Ene''24'!Z14 -> 9970388.4 | C6: 0.33
A7: Utilidad Marginal | B7: =B5-B6 -> 24668415 | C7: =(B7*C5)/B5 -> 0.71216129
A10: GASTOS VARIABLES | B10: =SUM(B11:B18) -> 5704357.1 | C10: =(B10*$C$5)/$B$5 -> 0.16468113
A11: COMISIONES BANCARIAS | B11: =+Gastos!D5 -> 215002.42 | C11: =(B11*$C$5)/$B$5 -> 0.0062069818
A12: COMISIONES DISTRIBUIDORES | B12: =+Gastos!D7 -> 800000 | C12: =(B12*$C$5)/$B$5 -> 0.023095486
A13: COMISIONES VENTAS | B13: =+Gastos!D11 -> 1393700 | C13: =(B13*$C$5)/$B$5 -> 0.040235224
A14: EXTRAORDINARIOS | B14: =+Gastos!D15 -> 1558543.5 | C14: =(B14*$C$5)/$B$5 -> 0.044994149
A15: FLETES | B15: =+Gastos!D17 -> 80000 | C15: =(B15*$C$5)/$B$5 -> 0.0023095486
A16: IMPUESTOS | B16: =+Gastos!D99 -> 657111.24 | C16: =(B16*$C$5)/$B$5 -> 0.01897038
A17: PUESTA EN MARCHA | B17: =+Gastos!D127 -> 1000000 | C17: =(B17*$C$5)/$B$5 -> 0.028869358
A19: GASTOS FIJOS | B19: =SUM(B20:B21) -> 13609544 | C19: =(B19*$C$5)/$B$5 -> 0.3928988
A20: LOCAL | B20: =+Gastos!D125 -> 7127175.5 | C20: =(B20*$C$5)/$B$5 -> 0.20575698
A21: SUELDOS | B21: =+Gastos!D140 -> 6482368.8 | C21: =(B21*$C$5)/$B$5 -> 0.18714182
A23: GASTOS TOTALES | B23: =+B10+B19 -> 19313901
A25: UTILIDAD NETA | B25: =B7-B10-B19 -> 5354513.2 | C25: =(B25*C5)/B5 -> 0.15458136
A28: INVERSIONES (Certificaciones)

Sheet Gastos
A1: Fecha | B1: Descripción | C1: Retiros Débito | D1: Rubro | E1: Categoría | F1: SubCategoría
A2: 45663 | B2: Comisión Transferencia Internet | D2: 11430 | E2: Comisiones Bancarias | F2: Gastos Bancarios
A3: 45664 | B3: Descuento Comercio | PayWay | ARIEL RODRIGUEZ | D3: 153272.42 | E3: Comisiones Bancarias | F3: PayWay
A4: 45688 | B4: Comisión Mantenimiento de Cuenta | D4: 50300 | E4: Comisiones Bancarias | F4: Comisiones Bancarias
B5: =+E2 -> Comisiones Bancarias | D5: =SUM(D2:D4) -> 215002.42
A6: 45684 | B6: Comisiones Javier | Dic´24 | D6: 800000 | E6: COMISIONES DISTRIBUIDORES | F6: COMISIONES DISTRIBUIDORES
B7: =+E6 -> COMISIONES DISTRIBUIDORES | D7: =SUM(D6) -> 800000
A8: 45660 | B8: Comisiones Cynthia | Dic'24 | D8: 560000 | E8: COMISIONES VENTAS | F8: COMISIONES VENTAS
A9: 45660 | B9: Comisiones Lelia | Dic'24 | D9: 643700 | E9: COMISIONES VENTAS | F9: COMISIONES VENTAS
A10: 45681 | B10: Comisiones Lelia | México | D10: 190000 | E10: COMISIONES VENTAS | F10: COMISIONES VENTAS
B11: =+E8 -> COMISIONES VENTAS | D11: =SUM(D8:D10) -> 1393700
A12: 45670 | B12: Pago | Mol y Band Fc 00003-00003097 | Base p/Horno | D12: 127000.5 | E12: Extraordinarios | F12: Base Horno
A13: 45673 | B13: Pago | Repjul | Lagatta Carlos Adrián | Compresor Mesa Fría | Fc 0006-00003182 | D13: 704042.64 | E13: Extraordinarios | F13: Compresor Mesa Fría
A14: 45687 | B14: Pago | Reld SACIFIA | Compresor Vitrina | Fc 00005-00221126 | D14: 727500.31 | E14: Extraordinarios | F14: Compresor
B15: =+E12 -> Extraordinarios | D15: =SUM(D12:D14) -> 1558543.5
A16: 45680 | B16: Fletero Daniel | D16: 80000 | E16: FLETE | F16: FLETE
B17: =+E16 -> FLETE | D17: =SUM(D16) -> 80000
A18: 45659 | B18: Impuesto Ley 25.413 | D18: 9.05 | E18: Impuestos | F18: Ley 25.413
A19: 45659 | B19: Impuesto Ley 25.413 | D19: 9.05 | E19: Impuestos | F19: Ley 25.413
A20: 45659 | B20: Impuesto Ley 25.413 | D20: 63.38 | E20: Impuestos | F20: Ley 25.413
A21: 45659 | B21: Impuesto Ley 25.413 | D21: 80.26 | E21: Impuestos | F21: Ley 25.413
A22: 45659 | B22: Impuesto Ley 25.413 | D22: 95.31 | E22: Impuestos | F22: Ley 25.413
A23: 45659 | B23: Impuesto Ley 25.413 | D23: 99 | E23: Impuestos | F23: Ley 25.413
A24: 45659 | B24: Impuesto Ley 25.413 | D24: 210.69 | E24: Impuestos | F24: Ley 25.413
A25: 45659 | B25: Impuesto Ley 25.413 | D25: 301.8 | E25: Impuestos | F25: Ley 25.413
A26: 45659 | B26: Impuesto Ley 25.413 | D26: 720 | E26: Impuestos | F26: Ley 25.413
A27: 45659 | B27: Impuesto Ley 25.413 | D27: 3031.31 | E27: Impuestos | F27: Ley 25.413
A28: 45659 | B28: Impuesto Ley 25.413 | D28: 3031.31 | E28: Impuestos | F28: Ley 25.413
A29: 45659 | B29: Impuesto Ley 25.413 | D29: 18716.9 | E29: Impuestos | F29: Ley 25.413
... A98: 45688 | B98: Ingresos Brutos | D98: 1509 | E98: Impuestos | F98: IIBB
B99: =+E18 -> Impuestos | D99: =SUM(D18:D98) -> 657111.24
A100: 45659 | B100: Pago | Débito Automático | Prosegur Alarmas | Fc 0011-01734777 | D100: 80198.26 | E100: Local | F100: Prosegur
A101: 45663 | B101: Pago | Telecom Teléfono | Débito Automático | Fc 4264-04753240 | D101: 26260.44 | E101: Local | F101: Teléfonos
A102: 45665 | B102: Pago | Edenor | Dic'24 | Fc 0026-42221491 | D102: 320546.39 | E102: Local | F102: Edenor
A103: 45667 | B103: Pago | MCG Ventilador | Fc 00004-00001963 | D103: 238249 | E103: Local | F103: Ventilador Local
A104: 45667 | B104: Pago | Débito Automático | Soluciones Online | Xubio | Fc 00002-00397253 | D104: 124630 | E104: Local | F104: Xubio
A105: 45670 | B105: Pago | INDUMENTARIA RGS S.R.L. | Chombas | Fc 00002-00000842 | D105: 100000 | E105: Local | F105: Uniformes
A106: 45670 | B106: Pago | Telecom Internet | Débito Automático | Fc 6364-08799773 | D106: 136902.53 | E106: Local | F106: Internet
A107: 45671 | B107: Fuertes Viviana | Alquiler Ene´25 | Fc 00002-00000224 | D107: 251090 | E107: Local | F107: Alquiler
A108: 45671 | B108: Pago | Petraccia Carlos | Bateria Autoelevador | Fc 00005-00011831 | D108: 1488000 | E108: Local | F108: Bateria Autoelevador
...

Sheet Ventas Ene'24
A1: Operador | B1: Fecha | C1: Cliente | D1: Producto | E1: Nº Serie | F1: N° Despacho | G1: # | H1: Valor Unitario | I1: Valor Total | J1: Dto. | K1: VALOR COTIZADO | L1: Facturado | M1: Tipo de IVA | N1: IVA | O1: Monto con IVA | P1: MONTO TOTAL | Q1: Galicia Más | R1: Mercado Pago | S1: PayWay | T1: Efectivo SmartChain | U1: TOTAL PAGADO | V1: Pendiente | W1: Factura | X1: CUIT | Y1: Forma de Pago | Z1: Costo Contable | AA1: Comisión 5% | AB1: <
A2: Lelia | B2: 45670 | C2: BRAIAN LEONEL JATAF | D2: FN1 PRO | E2: 202410318 | F2: 24 001 | C04 196596 G | G2: 1 | H2: 1080000 | I2: 1632001 | J2: 0.05 | K2: 1550400.9 | L2: 775200 | M2: 0.21 | N2: 162792 | O2: 937992 | P2: 1713192.9 | Q2: 937992 | T2: 775200 | U2: 1713192 | V2: 0.95 | W2: Fc B 0012 | X2: 20356126778 | Y2: Galicia | SmartChain | Z2: 264354 | AA2: 77520
D3: MESA | E3: PO24ITA018 | F3: 24 001 IC04 0985888 X | G3: 1 | H3: 370000 | Z3: 115357
D4: PALAS | E4: N/C | F4: N/C | G4: 2 | H4: 91000 | Z4: 61290
A5: Lelia | B5: 45675 | C5: ORLANDO SAEZ | ACATRAZ SA | D5: PRO GAS 90 | E5: 24146009 24146005 | F5: 24 001 | C04 196596 G | G5: 2 | H5: 4350000 | I5: 8700000 | J5: 0.15 | K5: 7395000 | L5: 7395000 | M5: 0.105 | N5: 776475 | O5: 8171475 | P5: 13999245 | Q5: 11362245 | T5: 2637000 | U5: 13999245 | V5: 0 | W5: Fc A 0056 | X5: 30702226216 | Y5: Galicia | SmartChain | Z5: 2143317 | AA5: 369750
D6: MESA FRIA | E6: YX20241009017 | F6: 24 001 | C04 196596 G | G6: 1 | H6: 5860000 | I6: 5860000 | J6: 0.1 | K6: 5274000 | L6: 2637000 | M6: 0.21 | N6: 553770 | O6: 3190770 | Z6: 2071520 | AA6: 263700
A7: Lelia | B7: 45681 | C7: JUAN NIGRO | D7: FN2 PRO | E7: 202403604 | F7: 24 001 | C04 196596 G | G7: 1 | H7: 2010000 | I7: 2010000 | J7: 0.1 | K7: 1809000 | L7: 1809000 | M7: 0.21 | N7: 379890 | O7: 2188890 | P7: 2188890 | Q7: 500000 | R7: 1500000 | T7: 188890 | U7: 2188890 | V7: 0 | W7: Fc B 0015 | X7: 20141876989 | Y7: Galicia | Mercado Pago | Efectivo | Z7: 492296 | AA7: 90450 | AB7: 801420
A8: Cynthia | B8: 45677 | C8: JORGE ADRIAN LEYES | D8: PRO GAS 106 | E8: G24038032015 | F8: 24 001 IC04 0985888 X | G8: 1 | H8: 3210000 | I8: 3210000 | J8: 0.05 | K8: 3179502 | L8: 3179502 | M8: 0.105 | N8: 320198 | O8: 3499700 | P8: 3499700 | Q8: 3499700 | U8: 3499700 | V8: 0 | W8: Fc B 0014 | X8: 23407978269 | Y8: Galicia | Z8: 748743 | AA8: 158975
A9: Cynthia | B9: 45672 | C9: EMILIANO ILLESCAS | D9: PRO GAS 602 | E9: 202410349 | F9: 24 001 | C04 196596 G | G9: 1 | H9: 5386000 | I9: 5386000 | J9: 0.1 | K9: 4847400 | L9: 2423700 | M9: 0.105 | N9: 254488.5 | O9: 2678188.5 | P9: 5101889 | T9: 5101889 | U9: 5101889 | V9: -0.5 | W9: Fc B 0018 | X9: 20280954560 | Y9: Efectivo | Z9: 1407253 | AA9: 242370
A10: Cynthia | B10: 45668 | C10: EMANUEL PEREYRA | D10: PRO GAS 90 | E10: 24146015 | F10: 24 001 | C04 196596 G | G10: 1 | H10: 4350000 | I10: 4350000 | J10: 0.05 | K10: 4132500 | L10: 2066250 | M10: 0.105 | N10: 216956.25 | O10: 2283206.2 | P10: 4459566 | Q10: 2559566.2 | T10: 1900000 | U10: 4459566.2 | V10: 0 | W10: Fc A 0057 | X10: 20274975734 | Y10: Efectivo | Z10: 1071659 | AA10: 206625
D11: PALA | E11: N/A | F11: N/A | G11: 1 | H11: 91000 | I11: 91000 | J11: 0 | K11: 91000 | L11: 91000 | M11: 0.21 | N11: 19110 | O11: 110110 | Z11: 30645 | AA11: 4550 | AB11: 612520
A12: Javier | B12: 45660 | C12: ARIEL RODRIGUEZ | D12: PRO GAS 90 | E12: 24146011 | F12: 24 001 | C04 196596 G | G12: 1 | H12: 4350000 | I12: 4350000 | K12: 4350000 | L12: 2175000 | M12: 0.105 | N12: 228375 | O12: 2403375 | P12: 4578375 | S12: 2403375 | T12: 2059200 | U12: 4462575 | V12: 115800 | W12: Fc B 0011 | X12: 20407945442 | Y12: Visa 3 Cuotas | Efectivo | Z12: 1071659
A13: Javier | B13: 45682 | C13: BARBARA GODOY | D13: FN2 PRO | E13: 202403592 | F13: 24 001 | C04 196596 G | G13: 1 | H13: 2010000 | I13: 2010000 | K13: 2010000 | L13: 703500 | M13: 0.21 | N13: 147735 | O13: 851235 | P13: 2157735 | T13: 1500000 | U13: 1500000 | V13: 657735 | W13: Fc B 0016 | X13: 27318849167 | Y13: Efectivo | Z13: 492296
I14: =SUM(I2:I13) -> 37599001 | J14: =+I14-K14 -> 2960198 | K14: 34638803 | L14: 23255152 | N14: 3059789.8 | O14: 26314942 | P14: 37698593 | U14: 36925057 | V14: 773535.45 | Z14: 9970388.4
Z15: 0.2878
V16: TIPO DE CAMBIO | X16: 1070

Sheet LISTA CONCEPTOS
A1: CUENTA | B1: SUBCUENTA
A2: Gasto de nómina | B2: ADQUISICION DE MERCANCIAS
A3: Gastos por servicios | B3: ALMACEN IFULL
A4: Gastos de venta | B4: ANTICIPO A PROVEEDORES
A5: Gastos financieros | B5: ASOCIACION NACIONAL DE TIENDAS DE AUTOSERVICIO Y DEPARTAMENTALES
A6: Gasto logistica | B6: CARGO NO IDENTIFICADO
A7: Reembolsos | B7: CASETAS
A8: Gastos de almacenaje | B8: COMISIONES BANCARIAS
A9: Viaticos Expo Pan WTC | B9: COMISIONES EUROFORNO
A10: Otros gastos operativos | B10: COMISIONES SOBRE VENTAS
A11: ANTICIPO A PROVEEDORES | B11: COMISIONES VENDEDORES
A12: CARGOS NO RECONOCIDOS BBVA | B12: CONSULTORIA ANA GPT
... A16: Gastos de Viaje y Transportacion | B16: EQUIPO DE PROTECCION PERSONAL
B17: EQUIPO PARA VENDEDORES (CARGADOR, USB,PILAS)
B18: ESTACIONAMIENTOS
B19: EXPO FOOD SERVICE DE MEXICO
B20: FERRETERIA Y HERRAMIENTAS PARA BODEGA TOLUCA
B21: GASOLINA FABIO
B22: GASTOS VARIOS
B23: GASTOS VARIOS (FABIO)
B24: HERRERIA BODEGA TOLUCA
B25: IMPUESTOS ANUALES
B26: IMPUESTOS FEDERALES
B27: IMPUESTOS ISR RET
B28: IMPUESTOS IVA RET
... B97: PUBLICIDAD DIGITAL MANTTO PAG. INTERNET-QUITO, ECUADOR
