Workbook

Sheet Feb´25
A1: Estado de Resultados 2025
A2: Concepto | B2: 45689 | C2: %
A3: Ventas Netas | B3: =+'Ventas Feb''24'!I21 -> 40965926 | C3: 1
A4: Descuentos Realizados | B4: =+'Ventas Feb''24'!J21 -> 1103000 | C4: =(B4*C3)/B3 -> 0.026924816
A5: Total Ingresos | B5: =B3-B4 -> 39862926 | C5: 1
A6: Costo total | B6: =+'Ventas Feb''24'!Y21 -> 9814343.6 | C6: 0.33
A7: Utilidad Marginal | B7: =B5-B6 -> 30048582 | C7: =(B7*C5)/B5 -> 0.75379771
A10: GASTOS VARIABLES | B10: =SUM(B11:B18) -> 4754899.9 | C10: =(B10*$C$5)/$B$5 -> 0.11928126
A11: COMISIONES BANCARIAS | B11: =+Gastos!C10 -> 263805.01 | C11: =(B11*$C$5)/$B$5 -> 0.0066178035
A12: COMISIONES DISTRIBUIDORES | B12: 1046123 | C12: =(B12*$C$5)/$B$5 -> 0.026243006
A13: COMISIONES VENTAS | B13: =+Gastos!C13 -> 1413000 | C13: =(B13*$C$5)/$B$5 -> 0.03544647
A14: EXTRAORDINARIOS | B14: =+Gastos!C20 -> 1142076.9 | C14: =(B14*$C$5)/$B$5 -> 0.028650103
A15: FLETES | B15: =+Gastos!C22 -> 170000 | C15: =(B15*$C$5)/$B$5 -> 0.0042646142
A16: IMPUESTOS | B16: =+Gastos!C141 -> 566175.94 | C16: =(B16*$C$5)/$B$5 -> 0.01420307
A17: MARKETING | B17: =+Gastos!C170 -> 153719.01 | C17: =(B17*$C$5)/$B$5 -> 0.0038561899
A18: PUESTA EN MARCHA | B18: 0 | C18: =(B18*$C$5)/$B$5 -> 0
A20: GASTOS FIJOS | B20: =SUM(B21:B22) -> 8284880.6 | C20: =(B20*$C$5)/$B$5 -> 0.20783423
A21: LOCAL | B21: =+Gastos!C168 -> 2899771 | C21: =(B21*$C$5)/$B$5 -> 0.072743556
A22: SUELDOS | B22: =+Gastos!C181 -> 5385109.7 | C22: =(B22*$C$5)/$B$5 -> 0.13509068
A24: GASTOS TOTALES | B24: =+B10+B20 -> 13039781
A26: UTILIDAD NETA | B26: =B7-B10-B20 -> 17008801 | C26: =(B26*C5)/B5 -> 0.42668222
A29: INVERSIONES

Sheet Gastos
A1: Fecha | B1: Descripción | C1: Rubro | D1: Categoría | E1: SubCategoría
A2: 45698 | B2: Comisiones Bancarias | Transferencia Internet | C2: 8255 | D2: Comisiones Bancarias | E2: Comisiones Bancarias
A3: 45712 | B3: Comisiones Bancarias | C3: 13881.1 | D3: Comisiones Bancarias | E3: Comisiones Bancarias
A4: 45713 | B4: Comsiones Exterior | C4: 4277.28 | D4: Comisiones Bancarias | E4: Exterior
A5: 45713 | B5: Comsiones Exterior | C5: 29940.96 | D5: Comisiones Bancarias | E5: Exterior
A6: 45713 | B6: Comsiones Exterior | C6: 142576 | D6: Comisiones Bancarias | E6: Exterior
A7: 45715 | B7: Comisión Op Intersucursal | C7: 11598.67 | D7: Comisiones Bancarias | E7: Comisiones Bancarias
A8: 45716 | B8: Comisión Op Intersucursal | C8: 2976 | D8: Comisiones Bancarias | E8: Comisiones Bancarias
A9: 45716 | B9: Comisión Mantenimiento de Cuenta | C9: 50300 | D9: Comisiones Bancarias | E9: Comisiones Bancarias
B10: =+D9 -> Comisiones Bancarias | C10: =SUM(C2:C9) -> 263805.01
A11: 45693 | B11: Comisiones Lelia | Ene´24 | C11: 801000 | D11: Comisones Ventas | E11: Comisones Ventas
A12: 45693 | B12: Comisiones Cynthia | Ene´24 | C12: 612000 | D12: Comisones Ventas | E12: Comisones Ventas
B13: =+D12 -> Comisones Ventas | C13: =SUM(C11:C12) -> 1413000
A14: 45702 | B14: Pago | FRANCISCO RICARDO JOSE | Regulador | Fc 00002-00001034 | C14: 258267.24 | D14: Extraordinarios | E14: Regulador
A15: 45694 | B15: Pago | ANTONIO FRANCISCO CELIO | Manómetro | Fc 0005-00034623 | C15: 65007.25 | D15: Extraordinarios | E15: Manómetro
A16: 45694 | B16: Pago | ANTONIO FRANCISCO CELIO | Manómetros | Fc 0005-00034625 | C16: 547908.38 | D16: Extraordinarios | E16: Manómetro
A17: 45699 | B17: Pago | Francisco Ricardo José | Regulador | Fc 00002_00001033 | C17: 128894.04 | D17: Extraordinarios | E17: Regulador
A18: 45695 | B18: Regulador de gas | C18: 106000 | D18: Extraordinarios | E18: Regulador
A19: 45699 | B19: Ridigas | Manguitos de 3/4 | Fc 0004-00012431 | C19: 36000.02 | D19: Extraordinarios | E19: Manguitos
B20: =+D19 -> Extraordinarios | C20: =SUM(C14:C19) -> 1142076.9
A21: 45692 | B21: Pago | RACCA DIANA ANDREA | Flete | Fc 00003-00000423/424 | C21: 170000 | D21: Flete | E21: Flete
B22: =+D21 -> Flete | C22: =SUM(C21) -> 170000
A23: 45691 | B23: Impuesto Ley 25.413 | C23: 9.05 | D23: Impuestos | E23: Ley 25.413
A24: 45691 | B24: Impuesto Ley 25.413 | C24: 9.05 | D24: Impuestos | E24: Ley 25.413
A25: 45691 | B25: Impuesto Ley 25.413 | C25: 63.38 | D25: Impuestos | E25: Ley 25.413
A26: 45691 | B26: Impuesto Ley 25.413 | C26: 301.8 | D26: Impuestos | E26: Ley 25.413
A27: 45691 | B27: Impuesto Ley 25.413 | C27: 3070.95 | D27: Impuestos | E27: Ley 25.413
A28: 45691 | B28: Impuesto Ley 25.413 | C28: 3070.95 | D28: Impuestos | E28: Ley 25.413
A29: 45692 | B29: Impuesto Ley 25.413 | C29: 157.56 | D29: Impuestos | E29: Ley 25.413
A30: 45692 | B30: Impuesto Ley 25.413 | C30: 499.96 | D30: Impuestos | E30: Ley 25.413
A31: 45692 | B31: Pago | Ganancias | Sicore | F744 | 01 2025 | C31: 65614.56 | D31: Impuestos | E31: Sicore
A32: 45693 | B32: Regimen Sircreb | C32: 150 | D32: Impuestos | E32: Sircreb
A33: 45693 | B33: Regimen Sircreb | C33: 155.31 | D33: Impuestos | E33: Sircreb
A34: 45693 | B34: Impuesto Ley 25.413 | C34: 393.69 | D34: Impuestos | E34: Ley 25.413
... A140: 45716 | B140: Ingresos Brutos | C140: 1509 | D140: Impuestos | E140: IIBB
B141: =+D140 -> Impuestos | C141: =SUM(C23:C140) -> 566175.94
A142: 45691 | B142: Pago | Telecom Internet | Débito Automático | Fc 4264-04888872 | C142: 26260.44 | D142: Local | E142: Internet
A143: 45691 | B143: Pago | Prosegur Alarmas | Débito Automático | Fc 0012-01804019 | C143: 83325.98 | D143: Local | E143: Alarma
A144: 45698 | B144: Pago | Verónica Rigante | Honorarios Contables | Fc 00002-00000882 | C144: 220000 | D144: Local | E144: Honorarios Contables
A145: 45698 | B145: Pago | Fuertes Viviana | Alquiler Feb´25 | Fc 00002-00000228 | C145: 264059 | D145: Local | E145: Alquiler
...

Sheet Ventas Feb'24
A1: Operador | B1: Fecha | C1: Cliente | D1: Producto | E1: Nº Serie | F1: N° Despacho | G1: # | H1: Valor Unitario | I1: Valor Total | J1: Dto. | K1: VALOR COTIZADO | L1: Facturado | M1: Tipo de IVA | N1: IVA | O1: Monto con IVA | P1: MONTO TOTAL | Q1: Galicia Más | R1: Mercado Pago | S1: Efectivo SmartChain | T1: TOTAL PAGADO | U1: Pendiente | V1: Factura | W1: CUIT | X1: Forma de Pago | Y1: Costo Contable
A2: Lelia | B2: 45693 | C2: CLAUDIO SOSA | D2: PRO ELECTRICO 90 | E2: 202403591 | F2: 24 001 | C04 196596 G | G2: 1 | H2: 3125000 | I2: 3125000 | J2: 0 | K2: 3125000 | L2: 1562500 | M2: 0.21 | N2: 328125 | O2: 1890625 | P2: 3453125 | Q2: 1890625 | S2: 1672500 | T2: 3563125 | U2: 110 | V2: Fc A 0003 | W2: 20-43915686-5 | X2: Efectivo | Galicia | Y2: 766152
D3: PALA | E3: N/A | F3: N/A | G3: 1 | H3: 91000 | I3: 91000 | J3: 0 | K3: 91000 | L3: 91000 | M3: 0.21 | N3: 19110 | O3: 110110 | P3: 110110 | Y3: 31715
A4: Lelia | B4: 45695 | C4: PABLO FUENTES | D4: PIEDRA 40x40 | E4: N/A | F4: N/A | G4: 1 | H4: 35000 | I4: 28925.62 | J4: 0 | K4: 28925.62 | L4: 28925.62 | M4: 0.21 | N4: 6074.38 | O4: 35000 | P4: 35000 | Q4: 35000 | T4: 35000 | U4: 0 | V4: Fc A 0004 | W4: 20-28607832-0 | X4: Galicia | Y4: 25188
A5: Lelia | B5: 45698 | C5: HERNAN LANDERECHE | D5: FN2 PRO | E5: 202410328 | F5: 24 001 | C04 196596 G | G5: 1 | H5: 2010000 | I5: 2010000 | J5: 0.15 | K5: 1708500 | L5: 1708500 | M5: 0.21 | N5: 358785 | O5: 2067285 | P5: 2067285 | S5: 2067000 | T5: 2067000 | U5: 285 | V5: Fc A 0002 | W5: 20200091168 | X5: Efectivo | Y5: 492296
A6: Lelia | B6: 45699 | C6: RODRIGO VILLAMONTE | D6: PRO GAS 90 | E6: 24146003 | 24146004 | F6: 24 001 | C04 196596 G | G6: 2 | H6: 4350000 | I6: 8700000 | J6: 0 | K6: 8700000 | L6: 4350000 | M6: 0.105 | N6: 456750 | O6: 4806750 | P6: 9156750 | Q6: 6806750 | S6: 2350000 | T6: 9156750 | U6: 0 | V6: Fc B 0004 | 0014 | W6: 20-31702968-4 | X6: Galicia | Y6: 2143317
A7: Lelia | B7: 45700 | C7: ALEJANDRO JIMENEZ | D7: PRO GAS 601 | E7: 202410347 | F7: 24 001 | C04 196596 G | G7: 1 | H7: 2865000 | I7: 2865000 | J7: 0 | K7: 2865000 | L7: 2865000 | M7: 0.105 | N7: 300825 | O7: 3165825 | P7: 3165825 | Q7: 3165825 | T7: 3165825 | U7: 0 | V7: Fc A 0007 | W7: 20281664868 | X7: Galicia | Y7: 748743
A8: Lelia | B8: 45701 | C8: VALENTINA SALVATIERRA | D8: PALA | E8: N/A | F8: N/A | G8: 1 | H8: 91000 | I8: 91000 | J8: 0 | K8: 91000 | L8: 45500 | M8: 0.21 | N8: 9555 | O8: 55055 | P8: 100555 | Q8: 55055 | S8: 45500 | T8: 100555 | U8: 0 | V8: Fc B 0007 | W8: 27-37726560-8 | X8: Galicia | Smartchain | Y8: 31715
A9: Lelia | B9: 45712 | C9: MARCELO CURI | D9: PRO GAS 106 | E9: 24038032009 | F9: 24 001 | C04 196596 G | G9: 1 | H9: 3210000 | I9: 3210000 | J9: 0 | K9: 3210000 | L9: 3210000 | M9: 0.105 | N9: 337050 | O9: 3547050 | P9: 3547050 | R9: 3547050 | T9: 3547050 | U9: 0 | V9: Fc A 0012 | W9: 20230418692 | X9: Visa | 3 Cuotas | Y9: 1130091
A10: Lelia | B10: 45715 | C10: MARIA VICTORIA COTUGNO | LUCERO,GUSTAVO SERGIO | D10: PRO GAS 106 | E10: 24038032005 | F10: 24 001 | C04 196596 G | G10: 1 | H10: 3210000 | I10: 3210000 | J10: 0 | K10: 3210000 | L10: 1605000 | M10: 0.105 | N10: 168525 | O10: 1773525 | P10: 3378525 | Q10: 1773525 | S10: 1605000 | T10: 3378525 | U10: 0 | V10: Fc A 0017 | W10: 27366439930 | X10: Galicia | Smartchain | Y10: 269105
A11: Cynthia | B11: 45685 | C11: FEDERICO RUSSO | D11: PRO ELECTRICO 90 | E11: ES240380320009 | F11: 24 001 IC04 0985888 X | G11: 1 | H11: 3125000 | I11: 3125000 | J11: 0.1 | K11: 2812500 | L11: 2812500.2 | M11: 0.21 | N11: 590625.04 | O11: 3403125.2 | P11: 3403125 | Q11: 3403125 | T11: 3403125 | U11: 0.04 | V11: Fc B 0017 | Anticipo Fc A 0001 | Saldo | W11: 20247843842 27045624779 | X11: Galicia | Y11: 766152
A12: Cynthia | B12: 45695 | C12: LEONARDO NICOLORICHE | D12: PRO GAS 90 | E12: 24146010 | F12: 24 001 | C04 196596 G | G12: 1 | H12: 4350000 | I12: 4350000 | J12: 0.1 | K12: 3915000 | L12: 3915000 | M12: 0.105 | N12: 411075 | O12: 4326075 | P12: 4326075 | Q12: 4326075 | T12: 4326075 | U12: 0 | V12: Fc B 0002 | W12: 20360034624 | X12: Galicia | Y12: 1071659
B13: 45700 | D13: PALA | E13: N/A | F13: N/A | G13: 1 | H13: 91000 | I13: 91000 | J13: 0 | K13: 91000 | L13: 91000 | M13: 0.21 | N13: 19110 | O13: 110110 | P13: 110110 | Q13: 110110 | T13: 110110 | U13: 0 | V13: Fc B 0005 | Y13: 30645
A14: Cynthia | B14: 45698 | C14: JUAN CARLOS BENITEZ | D14: PRO GAS 90 | E14: 24146002 | F14: 24 001 | C04 196596 G | G14: 1 | H14: 4350000 | I14: 4350000 | J14: 0 | K14: 4350000 | L14: 4350000 | M14: 0.105 | N14: 456750 | O14: 4806750 | P14: 4806750 | R14: 4806750 | T14: 4806750 | U14: 0 | V14: Fc B 0003 | W14: 20225762148 | X14: Visa | 3 Cuotas | Y14: 1071659
A15: Cynthia | B15: 45708 | C15: JUAN CARLOS BENITEZ | D15: Regulador | E15: N/A | F15: N/A | G15: 1 | H15: 106000 | I15: 106000 | J15: 0 | K15: 198000 | L15: 198000 | M15: 0.21 | N15: 41580 | O15: 239580 | P15: 239580 | R15: 239580 | T15: 239580 | U15: 0 | V15: Fc B 0010 | W15: 20225762148 | X15: Visa | 3 Cuotas | Y15: 106524
D16: Manómetro | E16: N/A | F16: N/A | G16: 1 | H16: 80000 | I16: 80000 | J16: 0 | Y16: 45666.25
D17: Manguito | E17: N/A | F17: N/A | G17: 1 | H17: 12000 | I17: 12000 | J17: 0 | Y17: 9917.36
A18: Cynthia | B18: 45713 | C18: LEONARDO MONTERO | D18: FN1 | E18: 202410324 | F18: 24 001 | C04 196596 G | G18: 1 | H18: 1080000 | I18: 1080000 | J18: 0.05 | K18: 1026000 | L18: 1117000 | M18: 0.21 | N18: 234570 | O18: 1351570 | P18: 1351570 | Q18: 211570 | S18: 1140000 | T18: 1351570 | U18: 0 | V18: Fc B 0012 | W18: 20-27565674-8 | X18: Efectivo | Galicia | Y18: 1070
D19: PALA | E19: N/A | F19: N/A | G19: 1 | H19: 91000 | I19: 91000 | J19: 0 | K19: 91000 | Y19: 1070
A20: Javier | B20: 45714 | C20: HERNAN SALINAS | D20: PRO GAS 90 | E20: 24146003 | F20: 24 001 | C04 196596 G | G20: 1 | H20: 4350000 | I20: 4350000 | J20: 0 | K20: 4350000 | L20: 2609236.2 | M20: 0.105 | N20: 273969.8 | O20: 2883206 | P20: 4623969.8 | Q20: 2883206 | S20: 1740764 | T20: 4623969.8 | U20: 0 | V20: Fc A 0013 | W20: 20273786512 | X20: Galicia | Y20: 1071659
I21: =SUM(I2:I20) -> 40965926 | J21: =+I21-K21 -> 1103000 | K21: =SUM(K2:K20) -> 39862926 | L21: 30559162 | N21: 4012479.2 | O21: 34571641 | P21: 43875405 | T21: 43875010 | U21: 395.04 | Y21: =SUM(Y2:Y20) -> 9814343.6
U23: TIPO DE CAMBIO | W23: 1070

Sheet LISTA CONCEPTOS
A1: CUENTA | B1: SUBCUENTA
A2: Gasto de nómina | B2: ADQUISICION DE MERCANCIAS
A3: Gastos por servicios | B3: ALMACEN IFULL
A4: Gastos de venta | B4: ANTICIPO A PROVEEDORES
A5: Gastos financieros | B5: ASOCIACION NACIONAL DE TIENDAS DE AUTOSERVICIO Y DEPARTAMENTALES
A6: Gasto logistica | B6: CARGO NO IDENTIFICADO
A7: Reembolsos | B7: CASETAS
A8: Gastos de almacenaje | B8: COMISIONES BANCARIAS
A9: Viaticos Expo Pan WTC | B9: COMISIONES EUROFORNO
A10: Otros gastos operativos | B10: COMISIONES SOBRE VENTAS
A11: ANTICIPO A PROVEEDORES | B11: COMISIONES VENDEDORES
A12: CARGOS NO RECONOCIDOS BBVA | B12: CONSULTORIA ANA GPT
... A16: Gastos de Viaje y Transportacion | B16: EQUIPO DE PROTECCION PERSONAL
B17: EQUIPO PARA VENDEDORES (CARGADOR, USB,PILAS)
B18: ESTACIONAMIENTOS
B19: EXPO FOOD SERVICE DE MEXICO
B20: FERRETERIA Y HERRAMIENTAS PARA BODEGA TOLUCA
B21: GASOLINA FABIO
B22: GASTOS VARIOS
B23: GASTOS VARIOS (FABIO)
B24: HERRERIA BODEGA TOLUCA
B25: IMPUESTOS ANUALES
B26: IMPUESTOS FEDERALES
B27: IMPUESTOS ISR RET
B28: IMPUESTOS IVA RET
... B97: PUBLICIDAD DIGITAL MANTTO PAG. INTERNET-QUITO, ECUADOR
