Workbook

Sheet Mar´25
A1: Estado de Resultados 2025
A2: Concepto | B2: 45717 | C2: %
A3: Ventas Netas | B3: =+'Ventas Mar''25'!I24 -> 31426799 | C3: 1
A4: Descuentos Realizados | B4: =+'Ventas Mar''25'!J24 -> 991280 | C4: =(B4*C3)/B3 -> 0.031542506
A5: Total Ingresos | B5: =B3-B4 -> 30435519 | C5: 1
A6: Costo total | B6: =+'Ventas Mar''25'!Y24 -> 9435025 | C6: 0.33
A7: Utilidad Marginal | B7: =B5-B6 -> 21000494 | C7: =(B7*C5)/B5 -> 0.68999954
A10: GASTOS VARIABLES | B10: =SUM(B11:B18) -> 5629696 | C10: =(B10*$C$5)/$B$5 -> 0.18497125
A11: COMISIONES BANCARIAS | B11: =+Gastos!C5 -> 71953.5 | C11: =(B11*$C$5)/$B$5 -> 0.0023641292
A12: COMISIONES DISTRIBUIDORES | B12: =+Gastos!C7 -> 728109 | C12: =(B12*$C$5)/$B$5 -> 0.023923003
A13: COMISIONES VENTAS | B13: =+Gastos!C10 -> 1764000 | C13: =(B13*$C$5)/$B$5 -> 0.057958598
A14: EXTRAORDINARIOS | B14: 0 | C14: =(B14*$C$5)/$B$5 -> 0
A15: FLETES | B15: =+Gastos!C12 -> 70000 | C15: =(B15*$C$5)/$B$5 -> 0.0022999444
A16: IMPUESTOS | B16: =+Gastos!C126 -> 995633.55 | C16: =(B16*$C$5)/$B$5 -> 0.032712882
A17: MARKETING | B17: 0 | C17: =(B17*$C$5)/$B$5 -> 0
A18: PUESTA EN MARCHA | B18: =+Gastos!C147 -> 2000000 | C18: =(B18*$C$5)/$B$5 -> 0.065712696
A20: GASTOS FIJOS | B20: =SUM(B21:B22) -> 7340388.2 | C20: =(B20*$C$5)/$B$5 -> 0.24117835
A21: LOCAL | B21: =+Gastos!C145 -> 2523811.2 | C21: =(B21*$C$5)/$B$5 -> 0.082923218
A22: SUELDOS | B22: =+Gastos!C154 -> 4816577 | C22: =(B22*$C$5)/$B$5 -> 0.15825513
A24: GASTOS TOTALES | B24: =+B10+B20 -> 12970084
A26: UTILIDAD NETA | B26: =B7-B10-B20 -> 8030409.8 | C26: =(B26*C5)/B5 -> 0.26384994
A29: INVERSIONES
A30: INVERSIONES (Certificaciones) | B30: =+Gastos!C157 -> 544500

Sheet Gastos
A1: Fecha | B1: Descripción | C1: Rubro | D1: Categoría | E1: SubCategoría
A2: 45726 | B2: Comisión Transferencia Internet | C2: 7620 | D2: Comisiones Bancarias | E2: Comisiones Bancarias
A3: 45736 | B3: Comisiones | C3: 14033.5 | D3: Comisiones Bancarias | E3: Comisiones Bancarias
A4: 45747 | B4: Comisión Mantenimiento de Cuenta | C4: 50300 | D4: Comisiones Bancarias | E4: Comisiones Bancarias
B5: =+D4 -> Comisiones Bancarias | C5: =SUM(C2:C4) -> 71953.5
A6: 45744 | B6: Pago | JAVIER MORANDO | Comisiones Ene-Feb-Mar´25 | Fc 0000-_00000131 | C6: 728109 | D6: Comisiones Distribuidores | E6: Comisiones Distribuidores
B7: =+D6 -> Comisiones Distribuidores | C7: =+C6 -> 728109
A8: 45742 | B8: Comisiones Cynthia | Feb´24 | C8: 614000 | D8: Comisiones Ventas | E8: Comisiones Ventas
A9: 45742 | B9: Comisiones Lelia | Feb´24 | C9: 1150000 | D9: Comisiones Ventas | E9: Comisiones Ventas
B10: =+D9 -> Comisiones Ventas | C10: =SUM(C8:C9) -> 1764000
A11: 45728 | B11: Pago | Diana Racca | Flete | Fc 00003-00000428 | C11: 70000 | D11: Fletes | E11: Fletes
B12: =+D11 -> Fletes | C12: =+C11 -> 70000
A13: 45721 | B13: Impuesto Ley 25.413 | C13: 0.27 | D13: Impuestos | E13: Ley 25.413
A14: 45721 | B14: Impuesto Ley 25.413 | C14: 0.36 | D14: Impuestos | E14: Ley 25.413
A15: 45721 | B15: Impuesto Ley 25.413 | C15: 0.89 | D15: Impuestos | E15: Ley 25.413
A16: 45721 | B16: Impuesto Ley 25.413 | C16: 1.06 | D16: Impuestos | E16: Ley 25.413
A17: 45721 | B17: Impuesto Ley 25.413 | C17: 9.05 | D17: Impuestos | E17: Ley 25.413
A18: 45721 | B18: Impuesto Ley 25.413 | C18: 9.05 | D18: Impuestos | E18: Ley 25.413
A19: 45721 | B19: Impuesto Ley 25.413 | C19: 17.86 | D19: Impuestos | E19: Ley 25.413
A20: 45721 | B20: Impuesto Ley 25.413 | C20: 61.73 | D20: Impuestos | E20: Ley 25.413
A21: 45721 | B21: Impuesto Ley 25.413 | C21: 63.38 | D21: Impuestos | E21: Ley 25.413
A22: 45721 | B22: Regimen Sircreb | C22: 75 | D22: Impuestos | E22: Sircreb
A23: 45721 | B23: Regimen Sircreb | C23: 75 | D23: Impuestos | E23: Sircreb
A24: 45721 | B24: Impuesto Ley 25.413 | C24: 87.27 | D24: Impuestos | E24: Ley 25.413
... A125: 45747 | B125: Ingresos Brutos | C125: 1509 | D125: Impuestos | E125: Ingresos Brutos
B126: =+D125 -> Impuestos | C126: =SUM(C13:C125) -> 995633.55
A127: 45721 | B127: Pago | Prosegur Alarmas | Fc 0011-01767443 | Débito Automático | C127: 41662.99 | D127: Local | E127: Alarma
A128: 45722 | B128: Pago | Telecom Internet | Fc 4264-05023771 | Débito Automático | C128: 26260.44 | D128: Local | E128: Internet
A129: 45723 | B129: Pago | Verónica Rigante | Honorarios Contables | Fc 00002-00000894 | C129: 220000 | D129: Local | E129: Honorarios Contables
A130: 45723 | B130: Pago | AGIP | ABL | Mar'25 | C130: 16383.28 | D130: Local | E130: ABL
A131: 45723 | B131: Pago | AGIP | ABL | Nov´24 | C131: 21067.88 | D131: Local | E131: ABL
A132: 45723 | B132: Pago | Viviana Fuertes | Alquiler Mar'25 | Fc 00002-00000233 | C132: 274347 | D132: Local | E132: Alquiler
A133: 45728 | B133: Pago | Soluciones Online | Xubio | Fc 00002-00413927 | Débito Automático | C133: 124630 | D133: Local | E133: Sistema Contable
A134: 45730 | B134: Pago | Telecom Teléfonos | Fc 6364-08928480 | Débito Automático | C134: 114739.8 | D134: Local | E134: Teléfonos
A135: 45735 | B135: Pago | Edenor | Fc 0026-58874226 | C135: 296036.36 | D135: Local | E135: Edenor
A136: 45735 | B136: Pago | Imprenta JM | Remitos | Fc 00002-00009856 | C136: 75020 | D136: Local | E136: Remitos
A137: 45744 | B137: Pago | AGIP | ABL | Ene´24 | C137: 10895.44 | D137: Local | E137: ABL
A138: 45744 | B138: Pago | AGIP | ABL | Mar´24 | C138: 11660.46 | D138: Local | E138: ABL
... A144: 45743 | B144: Micaela | Adelanto Macetas & Plantas Local | C144: 180000 | D144: Local | E144: Macetas & Plantas
B145: =+D144 -> Local | C145: =SUM(C127:C144) -> 2523811.2
...

Sheet Ventas Mar'25
A1: Operador | B1: Fecha | C1: Cliente | D1: Producto | E1: Nº Serie | F1: N° Despacho | G1: # | H1: Valor Unitario | I1: Valor Total | J1: Dto. | K1: VALOR COTIZADO | L1: Facturado | M1: Tipo de IVA | N1: IVA | O1: Monto con IVA | P1: MONTO TOTAL | Q1: Galicia Más | R1: Mercado Pago | S1: Efectivo SmartChain | T1: TOTAL PAGADO | U1: Pendiente | V1: Factura | W1: CUIT | X1: Forma de Pago | Y1: Costo Contable | Z1: Comisión 5%
A2: Cynthia | B2: 45729 | C2: SILVIA ISABEL ATTIANESE | D2: PRO GAS 90 | E2: 24146008 24146007 | F2: 24 001 | C04 196596 G | G2: 2 | H2: 4350000 | I2: 8700000 | J2: 0.05 | K2: 8265000 | L2: 4132500 | M2: 0.105 | N2: 433913 | O2: 4566413 | P2: 8698913 | Q2: 4566413 | S2: 4132500 | T2: 8698913 | U2: -1 | V2: Fc A 0020 | W2: 27-36991896-1 | X2: Galicia | Efectivo | Y2: 2143317 | Z2: 413250
A3: Cynthia | B3: 45736 | C3: SILVIA ISABEL ATTIANESE | D3: MANOMETRO | E3: N/A | F3: N/A | G3: 1 | H3: 80000 | I3: 80000 | J3: 0 | K3: 80000 | L3: 80000 | M3: 0.21 | N3: 16800 | O3: 96800 | P3: 96800 | S3: 96800 | T3: 96800 | U3: 0 | V3: Fc A 0024 | W3: 27-36991896-1 | X3: Efectivo | Y3: 45666
A4: Cynthia | B4: 45742 | C4: CACEROLASIEMPRE S.A. | D4: MANOMETRO | E4: N/A | F4: N/A | G4: 1 | H4: 80000 | I4: 80000 | J4: 0 | K4: 80000 | L4: 80000 | M4: 0.21 | N4: 16800 | O4: 96800 | P4: 239580 | Q4: 239580 | T4: 239580 | U4: 0 | V4: Fc A 0028 | W4: 30-71789652-8 | X4: Galicia | Y4: 45666
D5: REGULADOR | E5: N/A | F5: N/A | G5: 1 | H5: 106000 | I5: 106000 | J5: 0 | K5: 106000 | L5: 106000 | M5: 0.21 | N5: 22260 | O5: 128260 | Y5: 106722
D6: MANGUITO | E6: N/A | F6: N/A | G6: 1 | H6: 12000 | I6: 12000 | J6: 0 | K6: 12000 | L6: 12000 | M6: 0.21 | N6: 2520 | O6: 14520 | Y6: 9917
A7: Cynthia | B7: 45744 | C7: ANTEBI EMILIO FABIAN | D7: FN1 PRO | E7: 202410323 | F7: 24 001 | C04 196596 G | G7: 1 | H7: 1080000 | I7: 1080000 | J7: 0.05 | K7: 1026000 | L7: 513000 | M7: 0.21 | N7: 107730 | O7: 620730 | P7: 1133730 | S7: 1133730 | T7: 1133730 | U7: 0 | V7: Fc B 0024 | W7: 27044972935 | X7: Efectivo | Y7: 264354 | Z7: 51300
A8: Cynthia | B8: 45744 | C8: FRANCO ALVAREZ PAIS | D8: PRO ELECTRICO 90 | G8: 1 | H8: 3125000 | I8: 3125000 | J8: 0 | K8: 3125000 | L8: 3125000 | M8: 0.21 | N8: 656250 | O8: 3781250 | P8: 3781250 | Q8: 3781250 | T8: 3781250 | U8: 0 | W8: 20444128489 | X8: Galicia | Y8: 766152 | Z8: 156250
A9: Cynthia | B9: 45745 | C9: JAVIER VARGAS | D9: FN2 PRO | E9: 202410332 | F9: 24 001 | C04 196596 G | G9: 1 | H9: 2010000 | I9: 2010000 | J9: 0.1 | K9: 1809000 | L9: 904500 | M9: 0.21 | N9: 189945 | O9: 1094445 | P9: 2229072 | S9: 2228200 | T9: 2228200 | U9: 872 | V9: Fc A 0031 | W9: 20-34056178-4 | X9: Efectivo | Y9: 492296 | Z9: 90450
D10: PALA M35 | E10: N/A | F10: N/A | G10: 1 | H10: 91000 | I10: 91000 | J10: 0.1 | K10: 81900 | L10: 40950 | M10: 0.21 | N10: 8600 | O10: 49550 | Y10: 30645 | Z10: 4095
D11: KIT CAJAS X3 | E11: N/A | F11: N/A | G11: 1 | H11: 85400 | I11: 85400 | J11: 0.1 | K11: 76860 | L11: 38430 | M11: 0.21 | N11: 8070 | O11: 46500 | Y11: 22160 | Z11: 3843
D12: CURSO APYCE | E12: N/A | F12: N/A | G12: 1 | H12: 55000 | I12: 55000 | J12: 0.1 | K12: 49500 | L12: 24750 | M12: 0.21 | N12: 5198 | O12: 29948 | Z12: 2475
A13: Cynthia | B13: 45745 | C13: MARIANO DAMIANO | D13: MANOMETRO | E13: N/A | F13: N/A | G13: 1 | H13: 80000 | I13: 80000 | J13: 0 | K13: 80000 | L13: 80000 | M13: 0.21 | N13: 16800 | O13: 96800 | P13: 96800 | R13: 96800 | T13: 96800 | U13: 0 | V13: Fc A 0030 | W13: 20321870253 | X13: Mercado Pago | Y13: 45666 | Z13: - | AA13: 721663 | AB13: 14791260
A14: Lelia | B14: 45737 | C14: LUCAS | NOELIA CASTILLO SALINAS | D14: VITRINA | E14: RITA | F14: 24 001 IC04 0985888 X | G14: 1 | H14: 6999999 | I14: 6999999 | J14: 0 | K14: 6999999 | L14: 6998174 | M14: 0.21 | N14: 1469616 | O14: 8467790 | P14: 8467790 | Q14: 8467790 | T14: 8467790 | U14: 0 | V14: Fc B 0010/13 | Fc B 0001 | Fc B 0009 | Anticipos | W14: 27-94498628-1 | X14: Galicia | Y14: 3240685 | Z14: 350000
A15: Lelia | B15: 45737 | C15: JUAN CARLOS REGANZANI | D15: FN2 PRO | E15: 202410340 | F15: 24 001 | C04 196596 G | G15: 1 | H15: 2010000 | I15: 2010000 | J15: 0.1 | K15: 1809000 | L15: 1809000 | M15: 0.21 | N15: 379890 | O15: 2188890 | P15: 2440885 | Q15: 2440885 | T15: 2440885 | U15: 0 | V15: Fc A 0025 | W15: 20-16707945-9 | X15: Galicia | Y15: 492296 | Z15: 90450
D16: PALA M35 | E16: N/A | F16: N/A | G16: 1 | H16: 91000 | I16: 91000 | J16: 0.1 | K16: 81900 | L16: 81900 | M16: 0.21 | N16: 17199 | O16: 99099 | Y16: 30645 | Z16: 4095
D17: KIT CAJAS X3 | E17: N/A | F17: N/A | G17: 1 | H17: 85400 | I17: 85400 | J17: 0.1 | K17: 76860 | L17: 76860 | M17: 0.21 | N17: 16141 | O17: 93001 | Y17: 22160 | Z17: 3843
D18: CURSO APYCE | E18: N/A | F18: N/A | G18: 1 | H18: 55000 | I18: 55000 | J18: 0.1 | K18: 49500 | L18: 49500 | M18: 0.21 | N18: 10395 | O18: 59895 | Z18: 2475
A19: Lelia | B19: 45738 | C19: OSCAR GUILLERMO BADA | D19: PRO GAS 90 | E19: 24146016 | F19: 24 001 | C04 196596 G | G19: 1 | H19: 4350000 | I19: 4350000 | J19: 0 | K19: 4350000 | L19: 4350000 | M19: 0.105 | N19: 456750 | O19: 4806750 | P19: 5013660 | R19: 5013660 | T19: 5013660 | U19: 0 | V19: Fc A 0021 | W19: 20338132930 | X19: Mercado Pago | 3 Cuotas | Y19: 1071659 | Z19: 217500
D20: PALA M35 | E20: N/A | F20: N/A | G20: 1 | H20: 91000 | I20: 91000 | J20: 0 | K20: 91000 | L20: 91000 | M20: 0.21 | N20: 19110 | O20: 110110 | Y20: 30645 | Z20: 4550
D21: MANOMETRO | E21: N/A | F21: N/A | G21: 1 | H21: 80000 | I21: 80000 | J21: 0 | K21: 80000 | L21: 80000 | M21: 0.21 | N21: 16800 | O21: 96800 | Y21: 45666 | Z21: - | AA21: 672913 | AB21: 13538259
A22: Javier | B22: 45733 | C22: MATÍAS FEDERICO SÁNCHEZ | D22: FN1 PRO | E22: 202410316 | F22: 24 001 | C04 196596 G | G22: 1 | H22: 1080000 | I22: 1080000 | J22: 0.05 | K22: 1026000 | L22: 1026000 | M22: 0.21 | N22: 215460 | O22: 1241460 | P22: 1241460 | Q22: 1241460 | T22: 1241460 | U22: 0 | V22: Fc A 0021 | W22: 20-33876723-5 | X22: Galicia | Y22: 264354
A23: ML | B23: 45735 | C23: Nestor Javier Dominguez | D23: FN1 PRO | E23: 202410302 | F23: 24 001 | C04 196596 G | G23: 1 | H23: 1080000 | I23: 1080000 | J23: 0 | K23: 1080000 | L23: 1080000 | M23: 0.21 | N23: 226800 | O23: 1306800 | P23: 1306800 | R23: 1306800 | T23: 1306800 | U23: 0 | V23: Fc B 0020 | W23: 30182919 | X23: Mercado Pago | Y23: 264354
I24: =SUM(I2:I23) -> 31426799 | J24: =+I24-K24 -> 991280 | K24: =SUM(K2:K23) -> 30435519 | L24: 24779564 | N24: 4313046 | O24: 29092609 | P24: 34746739 | T24: 34745868 | U24: 871 | Y24: =SUM(Y2:Y23) -> 9435025
Y25: 0.31
U26: TIPO DE CAMBIO | W26: 1070

Sheet LISTA CONCEPTOS
A1: CUENTA | B1: SUBCUENTA
A2: Gasto de nómina | B2: ADQUISICION DE MERCANCIAS
A3: Gastos por servicios | B3: ALMACEN IFULL
A4: Gastos de venta | B4: ANTICIPO A PROVEEDORES
A5: Gastos financieros | B5: ASOCIACION NACIONAL DE TIENDAS DE AUTOSERVICIO Y DEPARTAMENTALES
A6: Gasto logistica | B6: CARGO NO IDENTIFICADO
A7: Reembolsos | B7: CASETAS
A8: Gastos de almacenaje | B8: COMISIONES BANCARIAS
A9: Viaticos Expo Pan WTC | B9: COMISIONES EUROFORNO
A10: Otros gastos operativos | B10: COMISIONES SOBRE VENTAS
A11: ANTICIPO A PROVEEDORES | B11: COMISIONES VENDEDORES
A12: CARGOS NO RECONOCIDOS BBVA | B12: CONSULTORIA ANA GPT
... A16: Gastos de Viaje y Transportacion | B16: EQUIPO DE PROTECCION PERSONAL
B17: EQUIPO PARA VENDEDORES (CARGADOR, USB,PILAS)
B18: ESTACIONAMIENTOS
B19: EXPO FOOD SERVICE DE MEXICO
B20: FERRETERIA Y HERRAMIENTAS PARA BODEGA TOLUCA
B21: GASOLINA FABIO
B22: GASTOS VARIOS
B23: GASTOS VARIOS (FABIO)
B24: HERRERIA BODEGA TOLUCA
B25: IMPUESTOS ANUALES
B26: IMPUESTOS FEDERALES
B27: IMPUESTOS ISR RET
B28: IMPUESTOS IVA RET
... B97: PUBLICIDAD DIGITAL MANTTO PAG. INTERNET-QUITO, ECUADOR
