Workbook

Sheet Abr'25
A1: Estado de Resultados 2025
A2: Concepto | B2: 45748 | C2: %
A3: Ventas Netas | B3: =+'Ventas Abr''25'!I26 -> 29161981 | C3: 1
A4: Descuentos Realizados | B4: =+'Ventas Abr''25'!J26 -> 886000 | C4: =(B4*C3)/B3 -> 0.030382024
A5: Total Ingresos | B5: =B3-B4 -> 28275981 | C5: 1
A6: Costo total | B6: =+'Ventas Abr''25'!Y26 -> 9552413 | C6: 0.33
A7: Utilidad Marginal | B7: =B5-B6 -> 18723568 | C7: =(B7*C5)/B5 -> 0.66217218
A10: GASTOS VARIABLES | B10: =SUM(B11:B18) -> 4495312.6 | C10: =(B10*$C$5)/$B$5 -> 0.1589799
A11: COMISIONES BANCARIAS | B11: =+Gastos!C10 -> 427100.38 | C11: =(B11*$C$5)/$B$5 -> 0.015104706
A12: COMISIONES DISTRIBUIDORES | B12: =+Gastos!C15 -> 211750 | C12: =(B12*$C$5)/$B$5 -> 0.007488688
A13: COMISIONES VENTAS | B13: =+Gastos!C13 -> 1390000 | C13: =(B13*$C$5)/$B$5 -> 0.04915833
A14: EXTRAORDINARIOS | B14: =+Gastos!C17 -> 635250 | C14: =(B14*$C$5)/$B$5 -> 0.022466064
A15: FLETES | B15: =+Gastos!C20 -> 693917.92 | C15: =(B15*$C$5)/$B$5 -> 0.024540896
A16: IMPUESTOS | B16: =+Gastos!C133 -> 1137294.3 | C16: =(B16*$C$5)/$B$5 -> 0.040221216
A17: MARKETING | B17: 0 | C17: =(B17*$C$5)/$B$5 -> 0
A18: PUESTA EN MARCHA | B18: 0 | C18: =(B18*$C$5)/$B$5 -> 0
A20: GASTOS FIJOS | B20: =SUM(B21:B22) -> 7994021.2 | C20: =(B20*$C$5)/$B$5 -> 0.28271419
A21: LOCAL | B21: =+Gastos!C150 -> 3167160.2 | C21: =(B21*$C$5)/$B$5 -> 0.11200885
A22: SUELDOS | B22: =+Gastos!C157 -> 4826861 | C22: =(B22*$C$5)/$B$5 -> 0.17070534
A24: GASTOS TOTALES | B24: =+B10+B20 -> 12489334
A26: UTILIDAD NETA | B26: =B7-B10-B20 -> 6234234.2 | C26: =(B26*C5)/B5 -> 0.22047809
A29: INVERSIONES
A30: INVERSIONES

Sheet Gastos
A1: Fecha | B1: Descripción | C1: Importe | D1: Categoría | E1: SubCategoría
A2: 45748 | B2: Comsiones Exterior | C2: 4323.16 | D2: Comisiones Bancarias | E2: Comisiones Bancarias
A3: 45748 | B3: Comsiones Exterior | C3: 30262.15 | D3: Comisiones Bancarias | E3: Comisiones Bancarias
A4: 45748 | B4: Comsiones Exterior | C4: 144105.5 | D4: Comisiones Bancarias | E4: Comisiones Bancarias
A5: 45770 | B5: Comisiones Bancarias | C5: 14224 | D5: Comisiones Bancarias | E5: Comisiones Bancarias
A6: 45777 | B6: Comsiión Mantenimiento de Cuenta | C6: 55000 | D6: Comisiones Bancarias | E6: Comisiones Bancarias
A7: 45755 | B7: Comsiones Exterior | C7: 4335.13 | D7: Comisiones Bancarias | E7: Comisiones Bancarias
A8: 45755 | B8: Comsiones Exterior | C8: 30345.94 | D8: Comisiones Bancarias | E8: Comisiones Bancarias
A9: 45755 | B9: Comsiones Exterior | C9: 144504.5 | D9: Comisiones Bancarias | E9: Comisiones Bancarias
B10: =+D9 -> Comisiones Bancarias | C10: =SUM(C2:C9) -> 427100.38
A11: 45748 | B11: Comisiones Cynthia | Mar´24 | C11: 720000 | D11: Comisiones Ventas | E11: Comisiones Ventas
A12: 45748 | B12: Comisiones Lelia | Mar´24 | C12: 670000 | D12: Comisiones Ventas | E12: Comisiones Ventas
B13: =+D12 -> Comisiones Ventas | C13: =SUM(C11:C12) -> 1390000
A14: 45749 | B14: Comisión Gonzalo Dacovih | Venta Emanuel | C14: 211750 | D14: Comisones Distribuidoes | E14: Comisones Distribuidoes
B15: =+D14 -> Comisones Distribuidoes | C15: =SUM(C14) -> 211750
A16: 45751 | B16: Pago | Mol y Band SA | Base p/horno | Fc 0003-00003157 | C16: 635250 | D16: Extraordinarios | E16: Base para Horno
B17: =+D16 -> Extraordinarios | C17: =SUM(C16) -> 635250
A18: 45762 | B18: Pago | Racca Diana | Flete | Fc 00003-00000432 | C18: 90000 | D18: Fletes | E18: Fletes
A19: 45777 | B19: Pago | Transporte Battaglia | Fletes | Fc 00002-00000918 | C19: 603917.92 | D19: Fletes | E19: Fletes
B20: =+D19 -> Fletes | C20: =SUM(C18:C19) -> 693917.92
A21: 45748 | B21: Regimen Sircreb | C21: 0.1 | D21: Impuestos | E21: Sircreb
A22: 45748 | B22: Impuesto Ley 25.413 | C22: 0.6 | D22: Impuestos | E22: Ley 25.413
A23: 45748 | B23: Impuesto Ley 25.413 | C23: 1.44 | D23: Impuestos | E23: Ley 25.413
A24: 45748 | B24: Impuesto Ley 25.413 | C24: 9.05 | D24: Impuestos | E24: Ley 25.413
A25: 45748 | B25: Impuesto Ley 25.413 | C25: 9.05 | D25: Impuestos | E25: Ley 25.413
A26: 45748 | B26: Impuesto Ley 25.413 | C26: 22.69 | D26: Impuestos | E26: Ley 25.413
A27: 45748 | B27: Impuesto Ley 25.413 | C27: 63.38 | D27: Impuestos | E27: Ley 25.413
A28: 45748 | B28: Impuesto Ley 25.413 | C28: 301.8 | D28: Impuestos | E28: Ley 25.413
A29: 45748 | B29: Regimen Sircreb | C29: 1477.33 | D29: Impuestos | E29: Sircreb
A30: 45748 | B30: Regimen Sircreb | C30: 1500 | D30: Impuestos | E30: Sircreb
A31: 45748 | B31: Regimen Sircreb | C31: 1500 | D31: Impuestos | E31: Sircreb
A32: 45748 | B32: Impuesto Ley 25.413 | C32: 3105.59 | D32: Impuestos | E32: Ley 25.413
... A132: 45777 | B132: Ingresos Brutos | C132: 1650 | D132: Impuestos | E132: Ingresos Brutos
B133: =+D132 -> Impuestos | C133: =SUM(C21:C132) -> 1137294.3
A134: 45751 | B134: Pago | Verónica Rigante | Honorarios Contables | Fc 00002-00000902 | C134: 243000 | D134: Local | E134: Honorarios Contables
A135: 45751 | B135: Pago | AGIP | ABL Abr'25 | C135: 21281.92 | D135: Local | E135: ABL
A136: 45751 | B136: Pago | Viviana Fuertes | Alquiler | Fc 00002-00000238 | C136: 274347 | D136: Local | E136: Alquiler
A137: 45751 | B137: Pago | DESARROLLO DE SOLUCIONES DIGITALES SRL | SUMAR App | Fc 00001-00000216 | C137: 363000 | D137: Local | E137: App Sumar
A138: 45754 | B138: Pago | Telecom | Internet | Fc 4264-05160645 | Débito Automático | C138: 26908.14 | D138: Local | E138: Internet
A139: 45757 | B139: Telecom | Teléfonos | Fc 6364-08992304 | Débito Automático | C139: 133342 | D139: Local | E139: Teléfonos
...

Sheet Ventas Abr'25
A1: Operador | B1: Fecha | C1: Cliente | D1: Producto | E1: Nº Serie | F1: N° Despacho | G1: # | H1: Valor Unitario | I1: Valor Total | J1: Dto. | K1: VALOR COTIZADO | L1: Facturado | M1: Tipo de IVA | N1: IVA | O1: Monto con IVA | P1: MONTO TOTAL | Q1: Galicia Más | R1: Mercado Pago | S1: Efectivo SmartChain | T1: TOTAL PAGADO | U1: Pendiente | V1: Factura | W1: CUIT | X1: Forma de Pago | Y1: Costo Contable
A2: Cynthia | B2: 45748 | C2: JULIAN NICOLAS RODRIGUEZ | D2: PRO GAS 90 | E2: 24146017 | F2: 24 001 | C04 196596 G | G2: 1 | H2: 4350000 | I2: 4350000 | J2: 0 | K2: 4350000 | L2: 2175000 | M2: 0.105 | N2: 228375 | O2: 2403375 | P2: 4578375 | S2: 4578375 | T2: 4578375 | U2: 0 | V2: Fc B 0027 | W2: 20312339626 | X2: Efectivo | Y2: 1251938
A3: Cynthia | B3: 45755 | C3: FELIPE MARCELO TABOADA | D3: FN1 PRO | E3: 202410300 | F3: 24 001 | C04 196596 G | G3: 1 | H3: 1080000 | I3: 1080000 | J3: 0.05 | K3: 1026000 | L3: 513000 | M3: 0.21 | N3: 107730 | O3: 620730 | P3: 1243840 | S3: 1244000 | T3: 1244000 | U3: -160 | V3: Fc A 0038 | W3: 23-23062151-9 | X3: Efectivo | Y3: 308825
D4: PALA 35 | E4: N/A | F4: N/A | G4: 1 | H4: 91000 | I4: 91000 | J4: 0 | K4: 91000 | L4: 91000 | M4: 0.21 | N4: 19110 | O4: 110110 | Y4: 35800
A5: Cynthia | B5: 45758 | C5: EZEQUIEL PINEYRUA CATERING LA CAPILLA S A | D5: PRO GAS 106 | E5: G24038032008 | F5: 24 001 IC04 0985888 X | G5: 1 | H5: 3210000 | I5: 3210000 | J5: 0 | K5: 3210000 | L5: 3210000 | M5: 0.105 | N5: 337050 | O5: 3547050 | P5: 3588630 | Q5: 3786630 | T5: 3786630 | U5: -198000 | V5: Fc A 0040 | W5: 30700986604 | X5: Galicia | Y5: 1320200
D6: PALA 35 | E6: sin cargo | F6: sin cargo | G6: 1 | H6: 91000 | I6: 91000 | J6: 1 | L6: 0 | N6: 0 | O6: 0 | Y6: 35800
D7: REGULADOR | E7: N/A | F7: N/A | G7: 1 | H7: 106000 | I7: 106000 | J7: 0 | K7: 0 | L7: 106000 | M7: 0.21 | N7: 22260 | O7: 128260 | Y7: 45666
D8: MANÓMETRO | E8: N/A | F8: N/A | G8: 1 | H8: 80000 | I8: 80000 | J8: 0 | K8: 0 | L8: 80000 | M8: 0.21 | N8: 16800 | O8: 96800 | Y8: 106722
D9: MANGUITO | E9: N/A | F9: N/A | G9: 1 | H9: 12000 | I9: 12000 | J9: 0 | K9: 0 | L9: 12000 | M9: 0.21 | N9: 2520 | O9: 14520 | Y9: 9917
A10: Cynthia | B10: 45762 | C10: CRISTIAN MARCELO LUNA | D10: PRO GAS 106 | E10: G23099106013 | F10: 24 001 IC04 0985888 X | G10: 1 | H10: 3210000 | I10: 3210000 | J10: 0 | K10: 3210000 | L10: 1605000 | M10: 0.105 | N10: 168525 | O10: 1773525 | P10: 3378525 | Q10: 1773525 | S10: 1605000 | T10: 3378525 | U10: 0 | V10: Fc A 0042 | W10: 20331587037 | X10: Galicia | Y10: 1320200
D11: PALA 35 | E11: sin cargo | F11: sin cargo | G11: 1 | H11: 91000 | I11: 91000 | J11: 1 | K11: 0 | Y11: 35800
A12: Cynthia | B12: 45758 | C12: EDELMAR DARIO FONS | D12: FN1 PRO | E12: 202410311 | F12: 24 001 | C04 196596 G | G12: 1 | H12: 1080000 | I12: 1080000 | J12: 0 | K12: 1080000 | L12: 1080000 | M12: 0.21 | N12: 226800 | O12: 1306800 | P12: 1306800 | Q12: 1306800 | T12: 1306800 | U12: 0 | V12: Fc A 0039 | Anticipo Fc A 0043 | W12: 20109705218 | X12: Galicia | Y12: 308825
D13: PALA 35 | E13: sin cargo | F13: sin cargo | G13: 1 | H13: 91000 | I13: 91000 | J13: 1 | Y13: 35800
A14: Cynthia | B14: 45770 | C14: PABLO FENOUIL | D14: PRO HOUSE | E14: PT 1816 3 OF 10 | F14: 24 001 | C04 196596 G | G14: 1 | H14: 1080000 | I14: 1080000 | J14: 0.15 | K14: 918000 | L14: 918000 | M14: 0.105 | N14: 96390 | O14: 1014390 | P14: 1014390 | S14: 1014390 | T14: 1014390 | U14: 0 | V14: Fc A 0044 | W14: 20-35666340-4 | X14: Efectivo | Y14: 314375
A15: Cynthia | B15: 45772 | C15: LEONARDO NICOLORICHE | D15: REGULADOR | E15: N/A | F15: N/A | G15: 1 | H15: 118000 | I15: 118000 | J15: 0 | K15: 118000 | L15: 118000 | M15: 0.21 | N15: 24780 | O15: 142780 | P15: 142780 | Q15: 142780 | T15: 142780 | U15: 0 | V15: Fc B 0031 | W15: 20360034624 | X15: Galicia | Y15: 45666
A16: Lelia | B16: 45748 | C16: LAUTARO EMANUEL VILLAMONTE | D16: PRO GAS 90 | E16: 24146018 | F16: 24 001 | C04 196596 G | G16: 1 | H16: 4350000 | I16: 4350000 | K16: 4350000 | L16: 2175000 | M16: 0.105 | N16: 228375 | O16: 2403375 | P16: 4578375 | S16: 4578375 | T16: 4578375 | U16: 0 | V16: Fc A 0036 | W16: 20370803928 | X16: Efectivo | Y16: 1251938
A17: Lelia | B17: 45751 | C17: RODRIGO VILLAMONTE | D17: REPUESTOS | E17: N/A | F17: N/A | G17: 1 | H17: 248981 | I17: 248981 | J17: 0 | K17: 248981 | L17: 248981 | M17: 0.21 | N17: 52286 | O17: 301267 | P17: 301267 | Q17: 301267 | T17: 301267 | U17: 0 | V17: Fc B 0028 | W17: 20-31702968-4 | X17: Galicia | Y17: 264017
A18: Lelia | B18: 45762 | C18: ERICK LASA | D18: FN1 PRO | E18: 202410315 | F18: 24 001 | C04 196596 G | G18: 1 | H18: 1080000 | I18: 1080000 | J18: 0 | K18: 1080000 | L18: 1080000 | M18: 0.21 | N18: 226800 | O18: 1306800 | P18: 1306800 | Q18: 1306800 | T18: 1306800 | U18: 0 | V18: Fc A 0041 | W18: 20-31248951-2 | X18: Galicia | Y18: 308825
D19: PALA 35 | E19: sin cargo | F19: sin cargo | G19: 1 | H19: 91000 | I19: 91000 | J19: 1 | K19: 0 | N19: 0 | O19: 0 | Y19: 35800
A20: Lelia | B20: 45750 | C20: GONZALO SACCO | D20: PRO GAS 90 | G20: 1 | H20: 4350000 | I20: 4350000 | J20: 0 | K20: 4350000 | L20: 2175000 | M20: 0.105 | N20: 228375 | O20: 2403375 | P20: 4578375 | S20: 4578400 | T20: 4578400 | U20: -25 | X20: Efectivo | Y20: 1251938
A21: Lelia | B21: 45773 | C21: DANIEL ERNESTO NAVARRO | D21: PALA 35 | E21: N/A | F21: N/A | G21: 1 | H21: 91000 | I21: 91000 | J21: 0 | K21: 91000 | L21: 91000 | M21: 0.21 | N21: 19110 | O21: 110110 | P21: 110110 | S21: 110110 | T21: 110110 | U21: 0 | V21: Fc A 0048 | W21: 20-24649777-0 | X21: Efectivo | Y21: 35800
A22: Javier | B22: 45748 | C22: DANIEL PABLO PINO | D22: FN1 PRO | E22: 202410309 | F22: 24 001 | C04 196596 G | G22: 1 | H22: 1080000 | I22: 1080000 | J22: 0.1 | K22: 972000 | L22: 486000 | M22: 0.21 | N22: 102060 | O22: 588060 | P22: 1074060 | S22: 1079000 | T22: 1079000 | U22: -4940 | V22: Fc B 0025 | W22: 20-30862008-6 | X22: Efectivo | Y22: 308825
A23: Javier | B23: 45750 | C23: MEDINA ALEJANDRO ESTEBAN | D23: FN2 PRO | E23: 202410327 | F23: 24 001 | C04 196596 G | G23: 1 | H23: 2010000 | I23: 2010000 | J23: 0 | K23: 2010000 | L23: 2010000 | M23: 0.21 | N23: 422100 | O23: 2432100 | P23: 2542210 | Q23: 2542210 | T23: 2542210 | U23: 0 | V23: Fc A 0035 | W23: 20-16636278-5 | X23: Galicia | Y23: 575113
D24: PALA 35 | E24: N/A | F24: N/A | G24: 1 | H24: 91000 | I24: 91000 | J24: 0 | K24: 91000 | L24: 91000 | M24: 0.21 | N24: 19110 | O24: 110110 | Y24: 35800
A25: Javier | B25: 45772 | C25: TOMAS ALURRALDE | D25: FN1 PRO | E25: 202410296 | F25: 24 001 | C04 196596 G | G25: 1 | H25: 1080000 | I25: 1080000 | J25: 0 | K25: 1080000 | L25: 540000 | M25: 0.21 | N25: 113400 | O25: 653400 | P25: 1193400 | Q25: 653400 | S25: 540000 | T25: 1193400 | U25: 0 | V25: Fc A 0045 | W25: 30-71620028-7 | X25: Galicia | Y25: 308825
I26: 29161981 | J26: 886000 | K26: 28275981 | L26: 16629981 | N26: 2661956 | O26: 21466937 | P26: 30937937 | T26: 31141062 | U26: -203125 | Y26: 9552413
Y27: 0.3378
U28: TIPO DE CAMBIO | W28: 1250

Sheet LISTA CONCEPTOS
A1: CUENTA | B1: SUBCUENTA
A2: Gasto de nómina | B2: ADQUISICION DE MERCANCIAS
A3: Gastos por servicios | B3: ALMACEN IFULL
A4: Gastos de venta | B4: ANTICIPO A PROVEEDORES
A5: Gastos financieros | B5: ASOCIACION NACIONAL DE TIENDAS DE AUTOSERVICIO Y DEPARTAMENTALES
A6: Gasto logistica | B6: CARGO NO IDENTIFICADO
A7: Reembolsos | B7: CASETAS
A8: Gastos de almacenaje | B8: COMISIONES BANCARIAS
A9: Viaticos Expo Pan WTC | B9: COMISIONES EUROFORNO
A10: Otros gastos operativos | B10: COMISIONES SOBRE VENTAS
A11: ANTICIPO A PROVEEDORES | B11: COMISIONES VENDEDORES
A12: CARGOS NO RECONOCIDOS BBVA | B12: CONSULTORIA ANA GPT
... A16: Gastos de Viaje y Transportacion | B16: EQUIPO DE PROTECCION PERSONAL
B17: EQUIPO PARA VENDEDORES (CARGADOR, USB,PILAS)
B18: ESTACIONAMIENTOS
B19: EXPO FOOD SERVICE DE MEXICO
B20: FERRETERIA Y HERRAMIENTAS PARA BODEGA TOLUCA
B21: GASOLINA FABIO
B22: GASTOS VARIOS
B23: GASTOS VARIOS (FABIO)
B24: HERRERIA BODEGA TOLUCA
B25: IMPUESTOS ANUALES
B26: IMPUESTOS FEDERALES
B27: IMPUESTOS ISR RET
B28: IMPUESTOS IVA RET
... B97: PUBLICIDAD DIGITAL MANTTO PAG. INTERNET-QUITO, ECUADOR
