Workbook

Sheet Dic'25
A1: Estado de Resultados 2025
A2: Concepto | B2: 45992 | C2: %
A3: Ventas Netas | B3: =ExportFacturacion3[[#Totals],[Precio con Descuento]] -> 1.0387471e+08 | C3: 1
A4: Descuentos Realizados | B4: =ExportFacturacion3[[#Totals],[Descuento]] -> 14803728 | C4: =(B4*C3)/B3 -> 0.14251523
A5: Total Ingresos | B5: =B3-B4 -> 89070980 | C5: 1
A6: Costo total | B6: =ExportFacturacion3[[#Totals],[Costo]] -> 21297688 | C6: 0.33
A7: Utilidad Marginal | B7: =B5-B6 -> 67773292 | C7: =(B7*C5)/B5 -> 0.76089083
A10: GASTOS VARIABLES | B10: =SUM(B11:B18) -> 78590580 | C10: =(B10*$C$5)/$B$5 -> 0.88233655
A11: COMISIONES BANCARIAS | B11: =+Gastos!C9 -> 254695.69 | C11: =(B11*$C$5)/$B$5 -> 0.0028594688
A12: COMISIONES DISTRIBUIDORES | B12: =+Gastos!C14 -> 2904720 | C12: =(B12*$C$5)/$B$5 -> 0.032611295
A13: COMISIONES VENTAS | B13: =+Gastos!C12 -> 2460259 | C13: =(B13*$C$5)/$B$5 -> 0.027621331
A14: EXTRAORDINARIOS | B14: =+Gastos!C27 -> 41388350 | C14: =(B14*$C$5)/$B$5 -> 0.46466706
A15: FLETES | B15: =+Gastos!C32 -> 1629673.6 | C15: =(B15*$C$5)/$B$5 -> 0.018296348
A16: IMPUESTOS | B16: =+Gastos!C129 -> 29952882 | C16: =(B16*$C$5)/$B$5 -> 0.33628104
A17: MARKETING | B17: 0 | C17: =(B17*$C$5)/$B$5 -> 0
A18: PUESTA EN MARCHA | B18: 0 | C18: =(B18*$C$5)/$B$5 -> 0
A20: GASTOS FIJOS | B20: =SUM(B21:B22) -> 13061572 | C20: =(B20*$C$5)/$B$5 -> 0.14664228
A21: LOCAL | B21: =+Gastos!C140 -> 1871177.6 | C21: =(B21*$C$5)/$B$5 -> 0.021007714
A22: SUELDOS | B22: =+Gastos!C155 -> 11190394 | C22: =(B22*$C$5)/$B$5 -> 0.12563457
A24: GASTOS TOTALES | B24: =+B10+B20 -> 91652152
A26: UTILIDAD NETA | B26: =B7-B10-B20 -> -23878860 | C26: =(B26*C5)/B5 -> -0.26808799
A29: INVERSIONES
A30: INVERSIONES

Sheet Gastos
A1: Fecha | B1: Descripción | C1: Importe | D1: Categoría | E1: SubCategoría
A2: 46006 | B2: Debito Com. Varias | Transf. al Ext. | C2: 14837.15 | D2: Impuestos | E2: Comisiones Bancarias
A3: 46006 | B3: Debito Com. Varias | Transf. al Ext. | C3: 185464.38 | D3: Impuestos | E3: Comisiones Bancarias
A4: 46007 | B4: Debito Com. Varias | C4: 50394.16 | D4: Impuestos | E4: Comisiones Bancarias
A5: 46010 | B5: Comision Gestion Transferancia Fondos entre Bancos | C5: 1000 | D5: Comisiones Bancarias | E5: Comisiones Bancarias
A6: 46014 | B6: Comision Gestion Transferancia Fondos entre Bancos | C6: 1000 | D6: Comisiones Bancarias | E6: Comisiones Bancarias
A7: 46021 | B7: Comision Gestion Transferancia Fondos entre Bancos | C7: 1000 | D7: Comisiones Bancarias | E7: Comisiones Bancarias
A8: 46021 | B8: Comision Gestion Transferancia Fondos entre Bancos | C8: 1000 | D8: Comisiones Bancarias | E8: Comisiones Bancarias
B9: Comisiones Bancarias | C9: =SUM(C2:C8) -> 254695.69
A10: 46017 | B10: Pago | Comisiones de Ventas Nov´2025 | Cynthia Magali Fernandez | C10: 1020640 | D10: Comisiones Ventas | E10: Comisiones Ventas
A11: 46017 | B11: Pago | Comisiones de Ventas Nov´2025 | Lelia Mariel Bertoni | C11: 1439619 | D11: Comisiones Ventas | E11: Comisiones Ventas
B12: Comisiones de Ventas | C12: =SUM(C10:C11) -> 2460259
A13: 46021 | B13: Comisiones Javier Nov´25 | C13: 2904720 | D13: Comisiones Ventas | E13: Comisiones Ventas
B14: Comisiones Distribuidores | C14: =SUM(C13) -> 2904720
A15: 45995 | B15: Pago | Desarrollo de Soluciones Digitales | Fact 0035 | Servicio APP Dic 2025 | C15: 581706.4 | D15: Otros Servicios | E15: App Sumar | F15: Servicio APP Noviembre 2025
A16: 46000 | B16: Pago | Fernandez Vaniva Alejandra | Fact 0087 | C16: 130696.4 | D16: Activos | E16: XVR de 8 Canales | F16: Implememtacion XVR de 8 Canales
A17: 46003 | B17: Pago | Transferencia entre cuentas propias | C17: 36385.43 | D17: Otros Servicios | E17: Gastos Administrativos | F17: Transferencia entre cuentas propias
A18: 46006 | B18: Pago | Guangdong Mingtai Baking Equipment Co LTD | Fact ARG04/06/25-03A | C18: 27202431 | D18: Activos | E18: Importacion | F18: Hornos
A19: 46008 | B19: Pago | Corp All Comercio Exterior | Fact 9173 | C19: 2106245.1 | D19: Otros Servicios | E19: Gastos Aduanales | F19: Anticipo OP 08 (Importacion)
A20: 46008 | B20: Pago | Corp All Comercio Exterior | Nota Debito 5776 | Pago Final | C20: 4276954.7 | D20: Otros Servicios | E20: Gastos Aduanales | F20: Anticipo OP 08 (Importacion)
A21: 46008 | B21: Pago | Lagatta Carlos Adrian | Fact 4564 | C21: 1013513.1 | D21: Activos | E21: Refacciones | F21: Motocompresores y conexiones de cobre
A22: 46010 | B22: Pago | Jaremczuk Carlos Basilio | Fact 2222 | C22: 1929143.4 | D22: Otros Servicios | E22: Gastos Administrativos | F22: Renovacion Certificados Hornos Gastronomicos
A23: 46014 | B23: Pago | Muñoz Ciro Tiziano | Fact 0007 | C23: 300000 | D23: Otros Servicios | E23: Puesta en Marcha | F23: Instalacion de Mesa Fria
A24: 46014 | B24: Pago | Leonardo Agustin Pascual | Fact 00002-00000078 | C24: 2200000 | D24: Marketing | E24: Publicidad | F24: Avisos publicitarios y film maker en RRSS y MIMA
A25: 46021 | B25: Pago | Tecnica Lift SA Fact 4285 | C25: 424031.4 | D25: Activos | E25: Equipo | F25: Stacker Electrico Cap 1500 kgs
A26: 46021 | B26: Pago | Autoelevadores y Gruas | Fact 7606 | C26: 1187243.4 | D26: Otros Servicios | E26: Fletes, Transportes y Guarda | F26: Desconsolidacion de contenedor y guarda mensual
B27: Extraordinarios | C27: =SUM(C15:C26) -> 41388350
A28: 46008 | B28: Pago | Battaglia Daniel Damian | Flete | Fact 1026 | C28: 394043.4 | D28: Logistica | E28: Fletes y Transportes | F28: Entregar Hornos en Local
A29: 46008 | B29: Pago | Autoelevadores y Gruas | Fact 7607 | C29: 142343.4 | D29: Logistica | E29: Fletes y Transportes | F29: Renta de autoelevador y flete para hornos
A30: 46008 | B30: Pago | Battaglia Daniel Damian | Flete | Fact 1026 | C30: 394043.4 | D30: Logistica | E30: Fletes y Transportes | F30: Entregar Hornos en Local
A31: 46014 | B31: Pago | Autoelevadores y Gruas | Fact 7615 | C31: 699243.4 | D31: Otros Servicios | E31: Fletes y Transportes | F31: Renta de autoelevador y Flete de Hornos
B32: Fletes | C32: =SUM(C28:C31) -> 1629673.6
A33: 45992 | B33: Imp. Ing. Brutos Sircreb | C33: 20 | D33: Impuestos | E33: Sircreb
A34: 45992 | B34: Imp. Ing. Brutos Sircreb | C34: 79.33 | D34: Impuestos | E34: Sircreb
A35: 45992 | B35: Pago | Servicios Imp Afip | C35: 27125589 | D35: Impuestos | E35: AFIP
A36: 45992 | B36: Imp. Ing. Brutos Sircreb | C36: 79.33 | D36: Impuestos | E36: Sircreb
A37: 45992 | B37: Imp. Ing. Brutos Sircreb | C37: 314.93 | D37: Impuestos | E37: Sircreb
A38: 45992 | B38: Impuesto Cre. Ley 25.413 | C38: 163368.75 | D38: Impuestos | E38: Ley 25.413
A39: 45992 | B39: Impuesto Cre. Ley 25.413 | C39: 29614.83 | D39: Impuestos | E39: Ley 25.413
A40: 45992 | B40: Impuesto Deb. Ley 25.413 | C40: 2.96 | D40: Impuestos | E40: Ley 25.413
...

Sheet Ventas Dic 2025 
A1: Tipo de Operacion | B1: ID Operacion | C1: Status | D1: Cliente | E1: Equipo | F1: Costo | G1: Vendedor | H1: Referido | I1: Correo | J1: Unitario | K1: Descuento | L1: Precio con Descuento | M1: IVA 10-5% | N1: IVA 21% | O1: Total Cotización | P1: % Factura | Q1: Total Factura | R1: Monto Factura | S1: Monto Efectivo
A2: Venta | B2: 541 | C2: Pendiente Despacho | D2: Gonzalo Sacco | E2: Horno Pro Gas 90 | F2: 1120931.7 | G2: Lelia | I2: saco.gonzalo@gmail.com | J2: 4350000 | K2: =ExportFacturacion3[[#This Row],[Unitario]]*30% -> 1305000 | L2: =ExportFacturacion3[[#This Row],[Unitario]]-ExportFacturacion3[[#This Row],[Descuento]] -> 3045000 | M2: 319.725,00 | N2: 0,00 | O2: 3.364.725,00 | P2: 100 | Q2: 3.364.725,00 | R2: 3.045.000,00 | S2: 0,00
A3: Venta | B3: 549 | C3: Pendiente Despacho | D3: Franca Grisolia | E3: Horno Pro Gas 12-2 | F3: 1114422.9 | G3: Stefania | I3: nannafranca@yahoo.com.ar | J3: 7000000 | K3: 1299900 | L3: =ExportFacturacion3[[#This Row],[Unitario]]-ExportFacturacion3[[#This Row],[Descuento]] -> 5700100 | M3: 598.510,50 | N3: 0,00 | O3: 6.298.610,50 | P3: 100 | Q3: 6.298.610,50 | R3: 5.700.100,00 | S3: 0,00
A4: Venta | B4: 561 | C4: Pendiente Despacho | D4: Esteban Bonorino | E4: Horno Pro Gas 12-2 | F4: 1114422.9 | G4: Stefania | I4: estebanbonorino@gmail.com | J4: 7000000 | K4: 1299900 | L4: =ExportFacturacion3[[#This Row],[Unitario]]-ExportFacturacion3[[#This Row],[Descuento]] -> 5700100 | M4: 598.510,50 | N4: 0,00 | O4: 6.298.610,50 | P4: 50 | Q4: 3.149.305,25 | R4: 2.850.050,00 | S4: 2.850.050,00
A5: Venta | B5: 564 | C5: Pendiente Despacho | D5: Guillermo Raul Torrado | E5: Horno Pro Gas 12-2 | F5: 1114422.9 | G5: Stefania | J5: 7000000 | K5: 1299900 | L5: =ExportFacturacion3[[#This Row],[Unitario]]-ExportFacturacion3[[#This Row],[Descuento]] -> 5700100 | M5: 598.510,50 | N5: 0,00 | O5: 6.298.610,50 | P5: 50 | Q5: 3.149.305,25 | R5: 2.850.050,00 | S5: 2.850.050,00
A6: Venta | B6: 568 | C6: Pendiente Despacho | D6: Cervelew Srl | E6: Horno Pro Gas 12-2 | F6: 1114422.9 | G6: Stefania | J6: 7000000 | K6: 1299900 | L6: =ExportFacturacion3[[#This Row],[Unitario]]-ExportFacturacion3[[#This Row],[Descuento]] -> 5700100 | M6: 598.510,50 | N6: 0,00 | O6: 6.298.610,50 | P6: 50 | Q6: 3.149.305,25 | R6: 2.850.050,00 | S6: 2.850.050,00
A7: Venta | B7: 583 | C7: Pendiente Despacho | D7: Sebastián Crespo | E7: Horno Pro Gas 6-1 | F7: 598486.37 | G7: Lelia | J7: 3867600 | K7: 800206.44 | L7: =ExportFacturacion3[[#This Row],[Unitario]]-ExportFacturacion3[[#This Row],[Descuento]] -> 3067393.6 | M7: 322.076,32 | N7: 22.260,00 | O7: 3.517.729,88 | P7: 50 | Q7: 1.758.864,94 | R7: 1.586.696,78 | S7: 1.586.696,78
E8: Regulador | J8: 106000 | K8: 0 | L8: 106000
A9: Venta | B9: 591 | C9: Pendiente Despacho | D9: Carolina Perez | E9: Horno Pro Gas 3-1 | G9: Lelia | H9: APYCE | J9: 3179000 | K9: 158950 | L9: =ExportFacturacion3[[#This Row],[Unitario]]-ExportFacturacion3[[#This Row],[Descuento]] -> 3020050 | M9: 317.105,25 | N9: 0,00 | O9: 3.337.155,25 | P9: 100 | Q9: 3.337.155,25 | R9: 3.020.050,00 | S9: 0,00
A10: Venta | B10: 599 | C10: Pendiente Despacho | D10: Jorge Alejandro Boscana | E10: Horno Pro Gas 12-2 | F10: 1114422.9 | G10: Roselin | I10: Jor.bosca@gmail.com | J10: 7000000 | K10: 1299900 | L10: =ExportFacturacion3[[#This Row],[Unitario]]-ExportFacturacion3[[#This Row],[Descuento]] -> 5700100 | M10: 598.510,50 | N10: 0,00 | O10: 6.298.610,50 | P10: 50 | Q10: 3.149.305,25 | R10: 2.850.050,00 | S10: 2.850.050,00
A11: Venta | B11: 602 | C11: Pendiente Despacho | D11: Sergio Gustavo Pizzi | E11: Horno FN2 Pro | F11: 398990.91 | G11: Stefania | I11: tanopizzi@hotmail.com | J11: 2211000 | K11: 0 | L11: 2211000 | M11: 232.155,00 | N11: 0,00 | O11: 2.443.155,00 | P11: 50 | Q11: 1.221.577,50 | R11: 1.105.500,00 | S11: 1.105.500,00
A12: Venta | B12: 610 | C12: Pendiente Despacho | D12: Alberto Dominguez | E12: Horno Pro Gas 12-2 | F12: 1114422.9 | G12: Roselin | I12: Jor.bosca@gmail.com | J12: 7000000 | K12: 1299900 | L12: =ExportFacturacion3[[#This Row],[Unitario]]-ExportFacturacion3[[#This Row],[Descuento]] -> 5700100 | M12: 598.510,50 | N12: 0,00 | O12: 6.298.610,50 | P12: 50 | Q12: 3.149.305,25 | R12: 2.850.050,00 | S12: 2.850.050,00
A13: Venta | B13: 615 | C13: Pendiente Despacho | D13: Jorge Daniel Portillo | E13: Horno Pro Gas 12-2 | F13: 1114422.9 | G13: Roselin | I13: Jor.bosca@gmail.com | J13: 7000000 | K13: 1299900 | L13: =ExportFacturacion3[[#This Row],[Unitario]]-ExportFacturacion3[[#This Row],[Descuento]] -> 5700100 | M13: 598.510,50 | N13: 0,00 | O13: 6.298.610,50 | P13: 50 | Q13: 3.149.305,25 | R13: 2.850.050,00 | S13: 2.850.050,00
A14: Venta | B14: 624 | C14: Pendiente Despacho | D14: Alberto Dominguez | E14: Amasadora 5.2 kg | F14: 599897.5 | G14: Stefania | I14: dalberto@hotmail.com | J14: 1844330 | K14: 92216.5 | L14: =ExportFacturacion3[[#This Row],[Unitario]]-ExportFacturacion3[[#This Row],[Descuento]] -> 1752113.5 | M14: 577.964,77 | N14: 0,00 | O14: 6.082.391,12 | P14: 100 | Q14: 6.082.391,12 | R14: 5.504.426,35 | S14: 0,00
E15: Mesa Fria 2 Puertas | F15: 1630897.6 | J15: 3949803 | K15: 197490.15 | L15: =ExportFacturacion3[[#This Row],[Unitario]]-ExportFacturacion3[[#This Row],[Descuento]] -> 3752312.9
A16: Venta | B16: 629 | C16: Pendiente Despacho | D16: Sergio Guastadini | E16: Mesa Fria 2 Puertas | F16: 1630897.6 | J16: 3949803 | K16: 197490.15 | L16: =ExportFacturacion3[[#This Row],[Unitario]]-ExportFacturacion3[[#This Row],[Descuento]] -> 3752312.9 | M16: 424.127,85 | N16: 0,00 | O16: 4.463.440,70 | P16: 100 | Q16: 4.463.440,70 | R16: 4.039.312,85 | S16: 0,00
E17: Perchero para Palas | F17: 92023 | J17: 287000 | K17: 0 | L17: 287000
A18: Venta | B18: 636 | C18: Pendiente Despacho | D18: Laurence Javier Druscovich | E18: Horno Pro Electrico 90 | G18: Stefania | I18: laurence@313led.com.ar | J18: 3620300 | K18: 181015 | L18: =ExportFacturacion3[[#This Row],[Unitario]]-ExportFacturacion3[[#This Row],[Descuento]] -> 3439285 | M18: 361.124,93 | N18: 0,00 | O18: 3.800.409,93 | P18: 50 | Q18: 1.900.204,96 | R18: 1.719.642,50 | S18: 1.719.642,50
A19: Venta | B19: 637 | C19: Pendiente Despacho | D19: Sergio Adrián Franchi | E19: Horno FN2 Pro | F19: 398990.91 | G19: Roselin | I19: Sergioadrianfranchi@gmail.com | J19: 2211000 | K19: 0 | L19: 2211000 | M19: 232.155,00 | N19: 0,00 | O19: 2.443.155,00 | P19: 50 | Q19: 1.221.577,50 | R19: 1.105.500,00 | S19: 1.105.500,00
A20: Venta | B20: 638 | C20: Pendiente Despacho | D20: Patricio Hernan Rienzi | E20: Regulador | G20: Roselin | J20: 106000 | K20: 0 | L20: 106000 | M20: 0,00 | N20: 22.260,00 | O20: 128.260,00 | P20: 100 | Q20: 128.260,00 | R20: 106.000,00 | S20: 0,00
A21: Venta | B21: 643 | C21: Pendiente Despacho | D21: Lucila De Camillis | E21: Horno Pro Gas 12-2 | F21: 1114422.9 | G21: Roselin | I21: Jor.bosca@gmail.com | J21: 7000000 | K21: 0 | L21: 7000000 | M21: 735.000,00 | N21: 0,00 | O21: 7.735.000,00 | P21: 100 | Q21: 7.735.000,00 | R21: 7.000.000,00 | S21: 0,00
A22: Venta | B22: 644 | C22: Pendiente Despacho | D22: Geronimo Capello Avanzino | E22: Horno Pro Gas 12-2 | F22: 1114422.9 | G22: Roselin | I22: Jor.bosca@gmail.com | J22: 7000000 | K22: 1299900 | L22: =ExportFacturacion3[[#This Row],[Unitario]]-ExportFacturacion3[[#This Row],[Descuento]] -> 5700100 | M22: 598.510,50 | N22: 0,00 | O22: 6.298.610,50 | P22: 50 | Q22: 3.149.305,25 | R22: 2.850.050,00 | S22: 2.850.050,00
A23: Venta | B23: 646 | C23: Pendiente Despacho | D23: Tomas Alurralde | E23: Horno FN2 Pro | F23: 398990.91 | G23: Roselin | I23: Sergioadrianfranchi@gmail.com | J23: 2211000 | K23: 0 | L23: 2211000 | M23: 232.155,00 | N23: 0,00 | O23: 2.443.155,00 | P23: 50 | Q23: 1.221.577,50 | R23: 1.105.500,00 | S23: 1.105.500,00
A24: Venta | B24: 649 | C24: Pendiente Despacho | D24: Jonatan Silvestri | E24: Cepillo para Piedra | F24: 29803.21 | G24: Roselin | H24: JAVIER | J24: 120100 | K24: 60050 | L24: =ExportFacturacion3[[#This Row],[Unitario]]-ExportFacturacion3[[#This Row],[Descuento]] -> 60050 | M24: 10.505,25 | N24: 0,00 | O24: 110.555,25 | P24: 100 | Q24: 110.555,25 | R24: 100.050,00 | S24: 0,00
E25: Pala Redonda de Giro | F25: 28147.47 | J25: 80000 | K25: 40000 | L25: =ExportFacturacion3[[#This Row],[Unitario]]-ExportFacturacion3[[#This Row],[Descuento]] -> 40000
A26: Venta | B26: 650 | C26: Pendiente Despacho | D26: Lucila De Camillis | E26: Cepillo para Piedra | F26: 29803.21 | G26: Stefania | H26: Ana GPT | I26: Elestabloalmacendecampo@hotmail.com | J26: 120100 | K26: 6005 | L26: =ExportFacturacion3[[#This Row],[Unitario]]-ExportFacturacion3[[#This Row],[Descuento]] -> 114095 | M26: 11.979,98 | N26: 0,00 | O26: 126.074,98 | P26: 50 | Q26: 63.037,49 | R26: 57.047,50 | S26: 57.047,50
A27: Venta | B27: 652 | C27: Pendiente Despacho | D27: Claudia Romina Gutiérrez | E27: Pala Redonda de Giro | F27: 28147.47 | G27: Roselin | I27: cjara3367@gmail.com | J27: 80000 | K27: 0 | L27: 80000 | M27: 31.300,50 | N27: 0,00 | O27: 329.400,50 | P27: 100 | Q27: 329.400,50 | R27: 298.100,00 | S27: 0,00
E28: Cepillo para Piedra | F28: 29803.21 | J28: 120100 | K28: 0 | L28: 120100
E29: Cuchilla Cortador | J29: 98000 | K29: 0 | L29: 98000
A30: Venta | B30: 653 | C30: Pendiente Despacho | D30: Alcides Viterman Miranda | E30: Horno Pro Gas 12-2 | F30: 1114422.9 | G30: Roselin | J30: 7000000 | K30: 350000 | L30: =ExportFacturacion3[[#This Row],[Unitario]]-ExportFacturacion3[[#This Row],[Descuento]] -> 6650000 | M30: 698.250,00 | N30: 0,00 | O30: 7.348.250,00 | P30: 50 | Q30: 3.674.125,00 | R30: 3.325.000,00 | S30: 3.325.000,00
A31: Venta | B31: 655 | C31: Pendiente Despacho | D31: Silvia Elizabeth De La Iglesia | E31: Horno FN2 Pro | F31: 398990.91 | G31: Roselin | I31: Sergioadrianfranchi@gmail.com | J31: 2211000 | K31: 0 | L31: 2211000 | M31: 232.155,00 | N31: 0,00 | O31: 2.443.155,00 | P31: 50 | Q31: 1.221.577,50 | R31: 1.105.500,00 | S31: 1.105.500,00
A32: Venta | B32: 661 | C32: Pendiente Despacho | D32: Juan Pedro Pacheco | E32: Horno Pro Gas 12-2 | F32: 1114422.9 | G32: Roselin | J32: 7000000 | K32: 350000 | L32: =ExportFacturacion3[[#This Row],[Unitario]]-ExportFacturacion3[[#This Row],[Descuento]] -> 6650000 | M32: 698.250,00 | N32: 0,00 | O32: 7.348.250,00 | P32: 50 | Q32: 3.674.125,00 | R32: 3.325.000,00 | S32: 3.325.000,00
A33: Venta | B33: 662 | C33: Pendiente Despacho | D33: Diego Tanjinson | E33: Cepillo para Piedra | F33: 29803.21 | G33: Roselin | J33: 120100 | K33: 0 | L33: 120100 | M33: 12.610,50 | N33: 0,00 | O33: 132.710,50 | P33: 50 | Q33: 66.355,25 | R33: 60.050,00 | S33: 60.050,00
A34: Venta | B34: 670 | C34: Pendiente Despacho | D34: Daniel Alvaro Cruz | E34: Horno FN2 Pro | F34: 398990.91 | G34: Roselin | I34: Sergioadrianfranchi@gmail.com | J34: 2211000 | K34: 221100 | L34: =ExportFacturacion3[[#This Row],[Unitario]]-ExportFacturacion3[[#This Row],[Descuento]] -> 1989900 | M34: 236.784,98 | N34: 0,00 | O34: 2.491.879,98 | P34: 50 | Q34: 1.245.939,99 | R34: 1.127.547,50 | S34: 1.127.547,50
E35: Aceitera | F35: 16557.34 | J35: 75100 | K35: 0 | L35: =ExportFacturacion3[[#This Row],[Unitario]]-ExportFacturacion3[[#This Row],[Descuento]] -> 75100
E36: Cepillo para Piedra | F36: 29803.21 | J36: 120100 | K36: 6005 | L36: =ExportFacturacion3[[#This Row],[Unitario]]-ExportFacturacion3[[#This Row],[Descuento]] -> 114095
E37: Pala Redonda de Giro | F37: 28147.47 | J37: 80000 | K37: 4000 | L37: =ExportFacturacion3[[#This Row],[Unitario]]-ExportFacturacion3[[#This Row],[Descuento]] -> 76000
A38: Venta | B38: 672 | C38: Pendiente Despacho | D38: Mauricio Alejandro Dutra | E38: Horno Pro Gas 90 | F38: 1120931.7 | G38: Stefania | I38: dutra_mauricio87@hotmail.com | J38: 4350000 | K38: 435000 | L38: =ExportFacturacion3[[#This Row],[Unitario]]-ExportFacturacion3[[#This Row],[Descuento]] -> 3915000 | M38: 411.075,00 | N38: 0,00 | O38: 4.326.075,00 | P38: 100 | Q38: 4.326.075,00 | R38: 3.915.000,00 | S38: 0,00
F39: =SUM(F2:F38) -> 21297688 | J39: =SUM(J2:J38) -> 118678436 | K39: =SUM(K2:K38) -> 14803728 | L39: =SUM(L2:L38) -> 1.0387471e+08

Sheet LISTA CONCEPTOS
A1: CUENTA | B1: SUBCUENTA
A2: Gasto de nómina | B2: ADQUISICION DE MERCANCIAS
A3: Gastos por servicios | B3: ALMACEN IFULL
A4: Gastos de venta | B4: ANTICIPO A PROVEEDORES
A5: Gastos financieros | B5: ASOCIACION NACIONAL DE TIENDAS DE AUTOSERVICIO Y DEPARTAMENTALES
A6: Gasto logistica | B6: CARGO NO IDENTIFICADO
A7: Reembolsos | B7: CASETAS
A8: Gastos de almacenaje | B8: COMISIONES BANCARIAS
A9: Viaticos Expo Pan WTC | B9: COMISIONES EUROFORNO
A10: Otros gastos operativos | B10: COMISIONES SOBRE VENTAS
A11: ANTICIPO A PROVEEDORES | B11: COMISIONES VENDEDORES
A12: CARGOS NO RECONOCIDOS BBVA | B12: CONSULTORIA ANA GPT
... A16: Gastos de Viaje y Transportacion | B16: EQUIPO DE PROTECCION PERSONAL
B17: EQUIPO PARA VENDEDORES (CARGADOR, USB,PILAS)
B18: ESTACIONAMIENTOS
B19: EXPO FOOD SERVICE DE MEXICO
B20: FERRETERIA Y HERRAMIENTAS PARA BODEGA TOLUCA
B21: GASOLINA FABIO
B22: GASTOS VARIOS
B23: GASTOS VARIOS (FABIO)
B24: HERRERIA BODEGA TOLUCA
B25: IMPUESTOS ANUALES
B26: IMPUESTOS FEDERALES
B27: IMPUESTOS ISR RET
B28: IMPUESTOS IVA RET
... B97: PUBLICIDAD DIGITAL MANTTO PAG. INTERNET-QUITO, ECUADOR
